Workbook

Sheet Diagrama de clases

Sheet Clases
A1: Clase | B1: Estereotipo | C1: Descripción
A2: UnidadMedida | B2: class | C2: Representa las unidades utilizadas por la pizzería para cuantificar los ingredientes, productos y demás elementos que requieren control de cantidades.
A3: TipoProducto | B3: class | C3: Representa la clasificación de cada producto que ofrece la pizzería, indicando si corresponde a una pizza, una bebida o una adición.
A4: ClaseMovimiento | B4: class | C4: Representa la clase de cada movimiento de inventario, indicando si corresponde a una entrada o a una salida de existencias.
A5: CategoriaOrigen | B5: class | C5: Representa la categoría de origen de la operación que genera un movimiento de inventario: una compra, una venta o un cambio de producto.
A6: TipoMovimiento | B6: class | C6: Representa el código de una operación concreta que mueve el inventario (cada detalle de compra, consumo de venta o cambio tiene el suyo); pertenece a una categoría de origen y lo comparten la operación y los movimientos que genera.
A7: Tamano | B7: class | C7: Representa las distintas presentaciones de tamaño en las que la pizzería puede ofrecer un producto; los productos que no son pizza usan "No aplica".
A8: Proveedor | B8: class | C8: Representa a las personas o empresas que suministran a la pizzería los insumos y productos necesarios para su operación.
A9: ProductoInterno | B9: class | C9: Representa cada insumo o producto que la pizzería compra y almacena en su inventario, ya sea que se consuma dentro de una receta o se venda directamente al cliente.
A10: Producto | B10: class | C10: Representa los artículos que la pizzería comercializa y que pueden ser vendidos al cliente, sirviendo como referencia para identificar y gestionar su oferta comercial.
A11: DetalleReceta | B11: class | C11: Representa cada uno de los ingredientes necesarios para elaborar una receta, indicando la cantidad requerida y la unidad de medida utilizada.
A12: Inventario | B12: class | C12: Representa las existencias disponibles de los insumos y productos que la pizzería necesita para operar y atender sus ventas.
... A23: Usuario | B23: class | C23: Representa a la persona que puede ingresar a la aplicación; solo los usuarios activos con rol Administrador pueden iniciar sesión.

Sheet Valores
A1: Estereotipo | B1: Relación | C1: Tipo relación | D1: Modificador acceso clase top level | E1: Tipo estructura | F1: Modificador acceso clase top level | G1: Tipo de dato | H1: Tipo acceso | I1: Tipo constructor | J1: Tipo parámetro | K1: Tipo método accesor | L1: Tipo de dato retorno método
A2: class | B2: Necesita de | C2: Asociación | D2: public | E2: final | F2: private | G2: byte/Byte | H2: static | I2: Defecto | J2: Por valor | K2: getter | L2: void
A3: abstract class | B3: Es usada por | C3: Agregación | D3: default | E3: no final | F3: protected | G3: short/Short | H3: no static | I3: Parametrizado | J3: Por referencia | K3: setter | L3: byte/Byte
A4: interface | C4: Composición | F4: default | G4: int/Integer | L4: short/Short
A5: enum | C5: Dependencia | F5: public | G5: long/Long | L5: int/Integer
A6: record | C6: Herencia | G6: float/Float | L6: long/Long
C7: Realización | G7: double/Double | L7: float/Float
G8: char/Character | L8: double/Double
G9: boolean/Boolean | L9: char/Character
G10: String | L10: boolean/Boolean
G11: Date | L11: String
G12: Otro | L12: Date
L13: Otro

Sheet UnidadMedida
A1: <-Volver al inicio
A2: =Clases!$A$1 -> Clase | B2: =Clases!A2 -> UnidadMedida
A3: =Clases!$B$1 -> Estereotipo | B3: =Clases!B2 -> class
A4: =Clases!$C$1 -> Descripción | B4: =Clases!C2 -> Representa las unidades utilizadas por la pizzería para cuantificar los ingredientes, productos y demás elementos que requieren control de cantidades.
A5: Modificador acceso: | B5: public
A6: Tipo clase: | B6: no final
A7: Relaciones
A8: Relación | B8: Tipo relación | E8: Estructura
A9: Es usada por | B9: Asociación | E9: ProductoInterno
A10: Es usada por | B10: Asociación | E10: DetalleReceta
A11: Es usada por | B11: Asociación | E11: Inventario
A12: Es usada por | B12: Asociación | E12: Lote
A13: Es usada por | B13: Asociación | E13: DetalleCompra
A14: Es usada por | B14: Asociación | E14: ConsumoVenta
A15: Es usada por | B15: Asociación | E15: Cambio
A17: Atributos
A18: Modificador de acceso | B18: Nombre | C18: Tipo de dato | E18: Tipo modificación atributo | F18: Tipo acceso atributo | G18: Valor por defecto | J18: Descripción atributo
C19: Tipo de dato | D19: ¿Cuál?
A20: private | B20: id | C20: Otro | D20: UUID | E20: no final | F20: no static | G20: 00000000-0000-0000-0000-000000000000 | J20: Identificador único de la unidad de medida.
A21: private | B21: unidadMedida | C21: String | E21: no final | F21: no static | G21: "" (cadena vacía) | J21: Símbolo o nombre corto de la unidad de medida (por ejemplo: g, kg, ml, l, und).
A22: private | B22: tipoMedida | C22: String | E22: no final | F22: no static | G22: "" (cadena vacía) | J22: Tipo de magnitud al que corresponde la unidad (peso, volumen o unidades).
A24: Constructores
A25: Modificador de acceso | B25: Nombre | C25: Tipo constructor | D25: Descripción | E25: Parámetros | M25: Excepciones
E26: Nombre | F26: Tipo de dato | G26: ¿Cuál? | H26: Tipo parámetro | I26: Tipo modificación atributo | J26: Descripción
A27: private | B27: =B2 -> UnidadMedida | C27: Parametrizado | D27: Constructor privado: crea la instancia de UnidadMedida copiando los valores ya saneados que reunió el Builder. Solo se invoca desde Builder.build(). | E27: builder | F27: Otro | G27: Builder | H27: Por valor | I27: no final | J27: Builder con los valores de los atributos de la clase.
A29: Métodos accesores
A30: Modificador de acceso | B30: Nombre | C30: Tipo método accesor | D30: Tipo modificación método | E30: Descripción | F30: Parámetros | L30: Tipo dato de retorno | N30: Excepciones
F31: Nombre | G31: Tipo de dato | H31: ¿Cuál? | I31: Tipo parámetro | J31: Tipo modificación atributo | K31: Descripción | L31: Tipo de dato | M31: ¿Cuál?
A32: public | B32: getId | C32: getter | D32: no final | E32: Método encargado de obtener el valor del atributo id. | L32: Otro | M32: UUID
A33: public | B33: getUnidadMedida | C33: getter | D33: no final | E33: Método encargado de obtener el valor del atributo unidadMedida. | L33: String
A34: public | B34: getTipoMedida | C34: getter | D34: no final | E34: Método encargado de obtener el valor del atributo tipoMedida. | L34: String
A36: Métodos
A37: Modificador de acceso | B37: Nombre | C37: Tipo acceso método | D37: Tipo modificación método | E37: Descripción | F37: Parámetros | L37: Tipo dato de retorno | N37: Excepciones
F38: Nombre | G38: Tipo de dato | H38: ¿Cuál? | I38: Tipo parámetro | J38: Tipo modificación atributo | K38: Descripción | L38: Tipo de dato | M38: ¿Cuál?
A39: public | B39: consultarUnidadesDeMedidaDisponibles | C39: static | D39: final | E39: Permite consultar las unidades de medida precargadas en el sistema para seleccionar la unidad adecuada al registrar cantidades de productos, ingredientes, compras, recetas o movimientos de inventario. | F39: unidadMedida | G39: Otro | H39: UnidadMedida | I39: Por valor | J39: no final | K39: Criterios necesarios para realizar la consulta de las unidades de medida disponibles. | L39: Otro | M39: List<UnidadMedida> | N39: No existen unidades de medida registradas en el catálogo. No existe una unidad de medida asociada al identificador indicado.
A40: public | B40: eliminarUnidadDeMedida | C40: no static | D40: no final | E40: Permite eliminar una unidad de medida que no esté siendo utilizada por ningún otro registro de la pizzería. | F40: id | G40: Otro | H40: UUID | I40: Por valor | J40: no final | K40: Identificador de la unidad de medida que se desea eliminar. | L40: void | N40: La unidad de medida que se desea eliminar no existe. La unidad de medida está siendo utilizada por un producto interno, un lote o un registro de inventario. La unidad de medida está siendo utilizada por un detalle de receta, un detalle de compra, un cambio o un consumo de venta.
A42: Builder (clase interna public static)
A43: Modificador de acceso | B43: Nombre | C43: Tipo acceso método | D43: Tipo modificación método | E43: Descripción | F43: Parámetros | L43: Tipo dato de retorno | N43: Excepciones
F44: Nombre | G44: Tipo de dato | H44: ¿Cuál? | I44: Tipo parámetro | J44: Tipo modificación atributo | K44: Descripción | L44: Tipo de dato | M44: ¿Cuál?
A45: public | B45: Builder | C45: no static | D45: no final | E45: Constructor del Builder: asigna a cada atributo su valor por defecto.
...

Sheet TipoProducto
A1: <-Volver al inicio
A2: =Clases!$A$1 -> Clase | B2: =Clases!A3 -> TipoProducto
A3: =Clases!$B$1 -> Estereotipo | B3: =Clases!B3 -> class
A4: =Clases!$C$1 -> Descripción | B4: =Clases!C3 -> Representa la clasificación de cada producto que ofrece la pizzería, indicando si corresponde a una pizza, una bebida o una adición.
A5: Modificador acceso: | B5: public
A6: Tipo clase: | B6: no final
A7: Relaciones
A8: Relación | B8: Tipo relación | E8: Estructura
A9: Es usada por | B9: Asociación | E9: Producto
A11: Atributos
A12: Modificador de acceso | B12: Nombre | C12: Tipo de dato | E12: Tipo modificación atributo | F12: Tipo acceso atributo | G12: Valor por defecto | J12: Descripción atributo
C13: Tipo de dato | D13: ¿Cuál?
A14: private | B14: id | C14: Otro | D14: UUID | E14: no final | F14: no static | G14: 00000000-0000-0000-0000-000000000000 | J14: Identificador único del tipo de producto.
A15: private | B15: nombre | C15: String | E15: no final | F15: no static | G15: "" (cadena vacía) | J15: Nombre de la clasificación del producto (Pizza, Bebida o Adición).
A17: Constructores
A18: Modificador de acceso | B18: Nombre | C18: Tipo constructor | D18: Descripción | E18: Parámetros | M18: Excepciones
E19: Nombre | F19: Tipo de dato | G19: ¿Cuál? | H19: Tipo parámetro | I19: Tipo modificación atributo | J19: Descripción
A20: private | B20: =B2 -> TipoProducto | C20: Parametrizado | D20: Constructor privado: crea la instancia de TipoProducto copiando los valores ya saneados que reunió el Builder. Solo se invoca desde Builder.build(). | E20: builder | F20: Otro | G20: Builder | H20: Por valor | I20: no final | J20: Builder con los valores de los atributos de la clase.
A22: Métodos accesores
A23: Modificador de acceso | B23: Nombre | C23: Tipo método accesor | D23: Tipo modificación método | E23: Descripción | F23: Parámetros | L23: Tipo dato de retorno | N23: Excepciones
F24: Nombre | G24: Tipo de dato | H24: ¿Cuál? | I24: Tipo parámetro | J24: Tipo modificación atributo | K24: Descripción | L24: Tipo de dato | M24: ¿Cuál?
A25: public | B25: getId | C25: getter | D25: no final | E25: Método encargado de obtener el valor del atributo id. | L25: Otro | M25: UUID
A26: public | B26: getNombre | C26: getter | D26: no final | E26: Método encargado de obtener el valor del atributo nombre. | L26: String
A28: Métodos
A29: Modificador de acceso | B29: Nombre | C29: Tipo acceso método | D29: Tipo modificación método | E29: Descripción | F29: Parámetros | L29: Tipo dato de retorno | N29: Excepciones
F30: Nombre | G30: Tipo de dato | H30: ¿Cuál? | I30: Tipo parámetro | J30: Tipo modificación atributo | K30: Descripción | L30: Tipo de dato | M30: ¿Cuál?
A31: public | B31: consultarTiposDeProductoDisponibles | C31: static | D31: final | E31: Permite consultar los tipos de producto disponibles en el sistema para clasificar un producto. | L31: Otro | M31: List<TipoProducto> | N31: No existen tipos de producto disponibles.
A32: public | B32: registrarTipoDeProducto | C32: no static | D32: no final | E32: Permite agregar un nuevo tipo de producto al catálogo, para cuando la pizzería empiece a manejar una categoría de producto que no exista todavía. | F32: tipoProducto | G32: Otro | H32: TipoProducto | I32: Por valor | J32: no final | K32: Nombre del nuevo tipo de producto que se desea registrar. | L32: Otro | M32: TipoProducto | N32: El dato ingresado no es válido según el tipo de dato, la obligatoriedad o el formato esperado. Ya existe otro tipo de producto registrado con el mismo Nombre.
A33: public | B33: actualizarTipoDeProducto | C33: no static | D33: no final | E33: Permite modificar el nombre de un tipo de producto que ya existe. | F33: tipoProducto | G33: Otro | H33: TipoProducto | I33: Por valor | J33: no final | K33: Identificador del tipo de producto que se desea modificar, junto con el nuevo nombre. | L33: Otro | M33: TipoProducto | N33: El tipo de producto no existe en el sistema. El nuevo dato ingresado no es válido según el tipo de dato, la obligatoriedad o el formato esperado.
A34: public | B34: eliminarTipoDeProducto | C34: no static | D34: no final | E34: Permite eliminar un tipo de producto que no tenga productos asociados que deban conservarse. | F34: id | G34: Otro | H34: UUID | I34: Por valor | J34: no final | K34: Identificador del tipo de producto que se desea eliminar. | L34: void | N34: El tipo de producto tiene productos asociados que deben conservarse. El tipo de producto no existe en el sistema.
A36: Builder (clase interna public static)
A37: Modificador de acceso | B37: Nombre | C37: Tipo acceso método | D37: Tipo modificación método | E37: Descripción | F37: Parámetros | L37: Tipo dato de retorno | N37: Excepciones
F38: Nombre | G38: Tipo de dato | H38: ¿Cuál? | I38: Tipo parámetro | J38: Tipo modificación atributo | K38: Descripción | L38: Tipo de dato | M38: ¿Cuál?
A39: public | B39: Builder | C39: no static | D39: no final | E39: Constructor del Builder: asigna a cada atributo su valor por defecto.
A40: public | B40: id | C40: no static | D40: no final | E40: Asigna el identificador recibido; si es nulo, asigna el identificador por defecto (00000000-0000-0000-0000-000000000000). | F40: id | G40: Otro | H40: UUID | I40: Por valor | J40: no final | K40: Valor que se desea asignar al atributo id. | L40: Otro | M40: Builder
A41: public | B41: nombre | C41: no static | D41: no final | E41: Asigna el texto recibido sin espacios en blanco al inicio y al final, con la primera letra en mayúscula y el resto en minúscula; si es nulo o vacío, asigna una cadena vacía. | F41: nombre | G41: String | I41: Por valor | J41: no final | K41: Valor que se desea asignar al atributo nombre. | L41: Otro | M41: Builder
A42: public | B42: build | C42: no static | D42: no final | E42: Crea la instancia de TipoProducto con los valores reunidos en el Builder, usando su constructor privado. | L42: Otro | M42: TipoProducto

Sheet ClaseMovimiento
A1: <-Volver al inicio
A2: =Clases!$A$1 -> Clase | B2: =Clases!A4 -> ClaseMovimiento
A3: =Clases!$B$1 -> Estereotipo | B3: =Clases!B4 -> class
A4: =Clases!$C$1 -> Descripción | B4: =Clases!C4 -> Representa la clase de cada movimiento de inventario, indicando si corresponde a una entrada o a una salida de existencias.
A5: Modificador acceso: | B5: public
A6: Tipo clase: | B6: no final
A7: Relaciones
A8: Relación | B8: Tipo relación | E8: Estructura
A9: Es usada por | B9: Asociación | E9: MovimientoInventario
A11: Atributos
A12: Modificador de acceso | B12: Nombre | C12: Tipo de dato | E12: Tipo modificación atributo | F12: Tipo acceso atributo | G12: Valor por defecto | J12: Descripción atributo
C13: Tipo de dato | D13: ¿Cuál?
A14: private | B14: id | C14: Otro | D14: UUID | E14: no final | F14: no static | G14: 00000000-0000-0000-0000-000000000000 | J14: Identificador único de la clase de movimiento.
A15: private | B15: nombre | C15: String | E15: no final | F15: no static | G15: "" (cadena vacía) | J15: Nombre de la clase de movimiento (Entrada o Salida): indica si el movimiento suma o resta inventario.
A17: Constructores
A18: Modificador de acceso | B18: Nombre | C18: Tipo constructor | D18: Descripción | E18: Parámetros | M18: Excepciones
E19: Nombre | F19: Tipo de dato | G19: ¿Cuál? | H19: Tipo parámetro | I19: Tipo modificación atributo | J19: Descripción
A20: private | B20: =B2 -> ClaseMovimiento | C20: Parametrizado | D20: Constructor privado: crea la instancia de ClaseMovimiento copiando los valores ya saneados que reunió el Builder. Solo se invoca desde Builder.build(). | E20: builder | F20: Otro | G20: Builder | H20: Por valor | I20: no final | J20: Builder con los valores de los atributos de la clase.
A22: Métodos accesores
A23: Modificador de acceso | B23: Nombre | C23: Tipo método accesor | D23: Tipo modificación método | E23: Descripción | F23: Parámetros | L23: Tipo dato de retorno | N23: Excepciones
F24: Nombre | G24: Tipo de dato | H24: ¿Cuál? | I24: Tipo parámetro | J24: Tipo modificación atributo | K24: Descripción | L24: Tipo de dato | M24: ¿Cuál?
A25: public | B25: getId | C25: getter | D25: no final | E25: Método encargado de obtener el valor del atributo id. | L25: Otro | M25: UUID
A26: public | B26: getNombre | C26: getter | D26: no final | E26: Método encargado de obtener el valor del atributo nombre. | L26: String
A28: Métodos
A29: Modificador de acceso | B29: Nombre | C29: Tipo acceso método | D29: Tipo modificación método | E29: Descripción | F29: Parámetros | L29: Tipo dato de retorno | N29: Excepciones
F30: Nombre | G30: Tipo de dato | H30: ¿Cuál? | I30: Tipo parámetro | J30: Tipo modificación atributo | K30: Descripción | L30: Tipo de dato | M30: ¿Cuál?
A31: public | B31: consultarClasesDeMovimientoDisponibles | C31: static | D31: final | E31: Permite consultar las clases de movimiento (Entrada o Salida) disponibles para clasificar un movimiento de inventario. | L31: Otro | M31: List<ClaseMovimiento> | N31: No existen clases de movimiento disponibles.
A33: Builder (clase interna public static)
A34: Modificador de acceso | B34: Nombre | C34: Tipo acceso método | D34: Tipo modificación método | E34: Descripción | F34: Parámetros | L34: Tipo dato de retorno | N34: Excepciones
F35: Nombre | G35: Tipo de dato | H35: ¿Cuál? | I35: Tipo parámetro | J35: Tipo modificación atributo | K35: Descripción | L35: Tipo de dato | M35: ¿Cuál?
A36: public | B36: Builder | C36: no static | D36: no final | E36: Constructor del Builder: asigna a cada atributo su valor por defecto.
A37: public | B37: id | C37: no static | D37: no final | E37: Asigna el identificador recibido; si es nulo, asigna el identificador por defecto (00000000-0000-0000-0000-000000000000). | F37: id | G37: Otro | H37: UUID | I37: Por valor | J37: no final | K37: Valor que se desea asignar al atributo id. | L37: Otro | M37: Builder
A38: public | B38: nombre | C38: no static | D38: no final | E38: Asigna el texto recibido sin espacios en blanco al inicio y al final, con la primera letra en mayúscula y el resto en minúscula; si es nulo o vacío, asigna una cadena vacía. | F38: nombre | G38: String | I38: Por valor | J38: no final | K38: Valor que se desea asignar al atributo nombre. | L38: Otro | M38: Builder
A39: public | B39: build | C39: no static | D39: no final | E39: Crea la instancia de ClaseMovimiento con los valores reunidos en el Builder, usando su constructor privado. | L39: Otro | M39: ClaseMovimiento

Sheet CategoriaOrigen
A1: <-Volver al inicio
A2: =Clases!$A$1 -> Clase | B2: =Clases!A5 -> CategoriaOrigen
A3: =Clases!$B$1 -> Estereotipo | B3: =Clases!B5 -> class
A4: =Clases!$C$1 -> Descripción | B4: =Clases!C5 -> Representa la categoría de origen de la operación que genera un movimiento de inventario: una compra, una venta o un cambio de producto.
A5: Modificador acceso: | B5: public
A6: Tipo clase: | B6: no final
A7: Relaciones
A8: Relación | B8: Tipo relación | E8: Estructura
A9: Es usada por | B9: Asociación | E9: TipoMovimiento
A11: Atributos
A12: Modificador de acceso | B12: Nombre | C12: Tipo de dato | E12: Tipo modificación atributo | F12: Tipo acceso atributo | G12: Valor por defecto | J12: Descripción atributo
C13: Tipo de dato | D13: ¿Cuál?
A14: private | B14: id | C14: Otro | D14: UUID | E14: no final | F14: no static | G14: 00000000-0000-0000-0000-000000000000 | J14: Identificador único de la categoría de origen.
A15: private | B15: nombre | C15: String | E15: no final | F15: no static | G15: "" (cadena vacía) | J15: Nombre de la categoría de origen de la operación que mueve el inventario (Compra, Venta o Cambio).
A17: Constructores
A18: Modificador de acceso | B18: Nombre | C18: Tipo constructor | D18: Descripción | E18: Parámetros | M18: Excepciones
E19: Nombre | F19: Tipo de dato | G19: ¿Cuál? | H19: Tipo parámetro | I19: Tipo modificación atributo | J19: Descripción
A20: private | B20: =B2 -> CategoriaOrigen | C20: Parametrizado | D20: Constructor privado: crea la instancia de CategoriaOrigen copiando los valores ya saneados que reunió el Builder. Solo se invoca desde Builder.build(). | E20: builder | F20: Otro | G20: Builder | H20: Por valor | I20: no final | J20: Builder con los valores de los atributos de la clase.
A22: Métodos accesores
A23: Modificador de acceso | B23: Nombre | C23: Tipo método accesor | D23: Tipo modificación método | E23: Descripción | F23: Parámetros | L23: Tipo dato de retorno | N23: Excepciones
F24: Nombre | G24: Tipo de dato | H24: ¿Cuál? | I24: Tipo parámetro | J24: Tipo modificación atributo | K24: Descripción | L24: Tipo de dato | M24: ¿Cuál?
A25: public | B25: getId | C25: getter | D25: no final | E25: Método encargado de obtener el valor del atributo id. | L25: Otro | M25: UUID
A26: public | B26: getNombre | C26: getter | D26: no final | E26: Método encargado de obtener el valor del atributo nombre. | L26: String
A28: Métodos
A29: Modificador de acceso | B29: Nombre | C29: Tipo acceso método | D29: Tipo modificación método | E29: Descripción | F29: Parámetros | L29: Tipo dato de retorno | N29: Excepciones
F30: Nombre | G30: Tipo de dato | H30: ¿Cuál? | I30: Tipo parámetro | J30: Tipo modificación atributo | K30: Descripción | L30: Tipo de dato | M30: ¿Cuál?
A31: public | B31: consultarCategoriasDeOrigenDisponibles | C31: static | D31: final | E31: Permite consultar las categorías de origen (Compra, Venta o Cambio) que indican que operación generó un movimiento de inventario. | L31: Otro | M31: List<CategoriaOrigen> | N31: No existen categorías de origen disponibles.
A33: Builder (clase interna public static)
A34: Modificador de acceso | B34: Nombre | C34: Tipo acceso método | D34: Tipo modificación método | E34: Descripción | F34: Parámetros | L34: Tipo dato de retorno | N34: Excepciones
F35: Nombre | G35: Tipo de dato | H35: ¿Cuál? | I35: Tipo parámetro | J35: Tipo modificación atributo | K35: Descripción | L35: Tipo de dato | M35: ¿Cuál?
A36: public | B36: Builder | C36: no static | D36: no final | E36: Constructor del Builder: asigna a cada atributo su valor por defecto.
A37: public | B37: id | C37: no static | D37: no final | E37: Asigna el identificador recibido; si es nulo, asigna el identificador por defecto (00000000-0000-0000-0000-000000000000). | F37: id | G37: Otro | H37: UUID | I37: Por valor | J37: no final | K37: Valor que se desea asignar al atributo id. | L37: Otro | M37: Builder
A38: public | B38: nombre | C38: no static | D38: no final | E38: Asigna el texto recibido sin espacios en blanco al inicio y al final, con la primera letra en mayúscula y el resto en minúscula; si es nulo o vacío, asigna una cadena vacía. | F38: nombre | G38: String | I38: Por valor | J38: no final | K38: Valor que se desea asignar al atributo nombre. | L38: Otro | M38: Builder
A39: public | B39: build | C39: no static | D39: no final | E39: Crea la instancia de CategoriaOrigen con los valores reunidos en el Builder, usando su constructor privado. | L39: Otro | M39: CategoriaOrigen

Sheet TipoMovimiento
A1: <-Volver al inicio
A2: =Clases!$A$1 -> Clase | B2: =Clases!A6 -> TipoMovimiento
A3: =Clases!$B$1 -> Estereotipo | B3: =Clases!B6 -> class
A4: =Clases!$C$1 -> Descripción | B4: =Clases!C6 -> Representa el código de una operación concreta que mueve el inventario (cada detalle de compra, consumo de venta o cambio tiene el suyo); pertenece a una categoría de origen y lo comparten la operación y los movimientos que genera.
A5: Modificador acceso: | B5: public
A6: Tipo clase: | B6: no final
A7: Relaciones
A8: Relación | B8: Tipo relación | E8: Estructura
A9: Necesita de | B9: Asociación | E9: CategoriaOrigen
A10: Es usada por | B10: Asociación | E10: DetalleCompra
A11: Es usada por | B11: Asociación | E11: ConsumoVenta
A12: Es usada por | B12: Asociación | E12: Cambio
A13: Es usada por | B13: Asociación | E13: MovimientoInventario
A15: Atributos
A16: Modificador de acceso | B16: Nombre | C16: Tipo de dato | E16: Tipo modificación atributo | F16: Tipo acceso atributo | G16: Valor por defecto | J16: Descripción atributo
C17: Tipo de dato | D17: ¿Cuál?
A18: private | B18: id | C18: Otro | D18: UUID | E18: no final | F18: no static | G18: 00000000-0000-0000-0000-000000000000 | J18: Código único de la operación concreta que genera movimientos de inventario (cada detalle de compra, consumo de venta o cambio tiene el suyo).
A19: private | B19: categoriaOrigen | C19: Otro | D19: CategoriaOrigen | E19: no final | F19: no static | G19: Instancia por defecto de CategoriaOrigen | J19: Categoría de origen a la que pertenece la operación (Compra, Venta o Cambio).
A21: Constructores
A22: Modificador de acceso | B22: Nombre | C22: Tipo constructor | D22: Descripción | E22: Parámetros | M22: Excepciones
E23: Nombre | F23: Tipo de dato | G23: ¿Cuál? | H23: Tipo parámetro | I23: Tipo modificación atributo | J23: Descripción
A24: private | B24: =B2 -> TipoMovimiento | C24: Parametrizado | D24: Constructor privado: crea la instancia de TipoMovimiento copiando los valores ya saneados que reunió el Builder. Solo se invoca desde Builder.build(). | E24: builder | F24: Otro | G24: Builder | H24: Por valor | I24: no final | J24: Builder con los valores de los atributos de la clase.
A26: Métodos accesores
A27: Modificador de acceso | B27: Nombre | C27: Tipo método accesor | D27: Tipo modificación método | E27: Descripción | F27: Parámetros | L27: Tipo dato de retorno | N27: Excepciones
F28: Nombre | G28: Tipo de dato | H28: ¿Cuál? | I28: Tipo parámetro | J28: Tipo modificación atributo | K28: Descripción | L28: Tipo de dato | M28: ¿Cuál?
A29: public | B29: getId | C29: getter | D29: no final | E29: Método encargado de obtener el valor del atributo id. | L29: Otro | M29: UUID
A30: public | B30: getCategoriaOrigen | C30: getter | D30: no final | E30: Método encargado de obtener el valor del atributo categoriaOrigen. | L30: Otro | M30: CategoriaOrigen
A32: Métodos
A33: Modificador de acceso | B33: Nombre | C33: Tipo acceso método | D33: Tipo modificación método | E33: Descripción | F33: Parámetros | L33: Tipo dato de retorno | N33: Excepciones
F34: Nombre | G34: Tipo de dato | H34: ¿Cuál? | I34: Tipo parámetro | J34: Tipo modificación atributo | K34: Descripción | L34: Tipo de dato | M34: ¿Cuál?
A35: public | B35: generarTipoDeMovimiento | C35: no static | D35: no final | E35: Genera un nuevo código de operación con su categoría de origen cada vez que se registra un detalle de compra, un consumo de venta o un cambio. | F35: categoriaOrigen | G35: Otro | H35: CategoriaOrigen | I35: Por valor | J35: no final | K35: Categoría de origen de la operación que genera el código. | L35: Otro | M35: TipoMovimiento | N35: La categoría de origen no existe. El identificador generado ya está siendo utilizado.
A36: public | B36: consultarTipoDeMovimiento | C36: static | D36: final | E36: Permite consultar un tipo de movimiento para conocer la categoría de origen de la operación. | F36: id | G36: Otro | H36: UUID | I36: Por valor | J36: no final | K36: Identificador del tipo de movimiento que se desea consultar. | L36: Otro | M36: TipoMovimiento | N36: No existe un tipo de movimiento con el identificador indicado.
A38: Builder (clase interna public static)
A39: Modificador de acceso | B39: Nombre | C39: Tipo acceso método | D39: Tipo modificación método | E39: Descripción | F39: Parámetros | L39: Tipo dato de retorno | N39: Excepciones
F40: Nombre | G40: Tipo de dato | H40: ¿Cuál? | I40: Tipo parámetro | J40: Tipo modificación atributo | K40: Descripción | L40: Tipo de dato | M40: ¿Cuál?
A41: public | B41: Builder | C41: no static | D41: no final | E41: Constructor del Builder: asigna a cada atributo su valor por defecto.
A42: public | B42: id | C42: no static | D42: no final | E42: Asigna el identificador recibido; si es nulo, asigna el identificador por defecto (00000000-0000-0000-0000-000000000000). | F42: id | G42: Otro | H42: UUID | I42: Por valor | J42: no final | K42: Valor que se desea asignar al atributo id. | L42: Otro | M42: Builder
A43: public | B43: categoriaOrigen | C43: no static | D43: no final | E43: Asigna el valor recibido; si es nulo, asigna la instancia por defecto de CategoriaOrigen. | F43: categoriaOrigen | G43: Otro | H43: CategoriaOrigen | I43: Por valor | J43: no final | K43: Valor que se desea asignar al atributo categoriaOrigen. | L43: Otro | M43: Builder
A44: public | B44: build | C44: no static | D44: no final | E44: Crea la instancia de TipoMovimiento con los valores reunidos en el Builder, usando su constructor privado. | L44: Otro | M44: TipoMovimiento

Sheet Tamano
A1: <-Volver al inicio
A2: =Clases!$A$1 -> Clase | B2: =Clases!A7 -> Tamano
A3: =Clases!$B$1 -> Estereotipo | B3: =Clases!B7 -> class
A4: =Clases!$C$1 -> Descripción | B4: =Clases!C7 -> Representa las distintas presentaciones de tamaño en las que la pizzería puede ofrecer un producto; los productos que no son pizza usan "No aplica".
A5: Modificador acceso: | B5: public
A6: Tipo clase: | B6: no final
A7: Relaciones
A8: Relación | B8: Tipo relación | E8: Estructura
A9: Es usada por | B9: Asociación | E9: Producto
A11: Atributos
A12: Modificador de acceso | B12: Nombre | C12: Tipo de dato | E12: Tipo modificación atributo | F12: Tipo acceso atributo | G12: Valor por defecto | J12: Descripción atributo
C13: Tipo de dato | D13: ¿Cuál?
A14: private | B14: id | C14: Otro | D14: UUID | E14: no final | F14: no static | G14: 00000000-0000-0000-0000-000000000000 | J14: Identificador único del tamaño.
A15: private | B15: tamano | C15: String | E15: no final | F15: no static | G15: "" (cadena vacía) | J15: Nombre de la presentación de tamaño (Grande, Mediana, Pequeña o No aplica).
A17: Constructores
A18: Modificador de acceso | B18: Nombre | C18: Tipo constructor | D18: Descripción | E18: Parámetros | M18: Excepciones
E19: Nombre | F19: Tipo de dato | G19: ¿Cuál? | H19: Tipo parámetro | I19: Tipo modificación atributo | J19: Descripción
A20: private | B20: =B2 -> Tamano | C20: Parametrizado | D20: Constructor privado: crea la instancia de Tamano copiando los valores ya saneados que reunió el Builder. Solo se invoca desde Builder.build(). | E20: builder | F20: Otro | G20: Builder | H20: Por valor | I20: no final | J20: Builder con los valores de los atributos de la clase.
A22: Métodos accesores
A23: Modificador de acceso | B23: Nombre | C23: Tipo método accesor | D23: Tipo modificación método | E23: Descripción | F23: Parámetros | L23: Tipo dato de retorno | N23: Excepciones
F24: Nombre | G24: Tipo de dato | H24: ¿Cuál? | I24: Tipo parámetro | J24: Tipo modificación atributo | K24: Descripción | L24: Tipo de dato | M24: ¿Cuál?
A25: public | B25: getId | C25: getter | D25: no final | E25: Método encargado de obtener el valor del atributo id. | L25: Otro | M25: UUID
A26: public | B26: getTamano | C26: getter | D26: no final | E26: Método encargado de obtener el valor del atributo tamano. | L26: String
A28: Métodos
A29: Modificador de acceso | B29: Nombre | C29: Tipo acceso método | D29: Tipo modificación método | E29: Descripción | F29: Parámetros | L29: Tipo dato de retorno | N29: Excepciones
F30: Nombre | G30: Tipo de dato | H30: ¿Cuál? | I30: Tipo parámetro | J30: Tipo modificación atributo | K30: Descripción | L30: Tipo de dato | M30: ¿Cuál?
A31: public | B31: consultarTamanosDisponibles | C31: static | D31: final | E31: Permite consultar los tamaños disponibles en el sistema para definir el tamaño de un producto. | L31: Otro | M31: List<Tamano> | N31: No existen tamaños disponibles.
A32: public | B32: registrarTamano | C32: no static | D32: no final | E32: Permite agregar un nuevo tamaño al catálogo, para cuando la pizzería empiece a ofrecer una presentación que no exista todavía. | F32: tamano | G32: Otro | H32: Tamano | I32: Por valor | J32: no final | K32: Nombre del nuevo tamaño que se desea registrar. | L32: Otro | M32: Tamano | N32: El dato ingresado no es válido según el tipo de dato, la obligatoriedad o el formato esperado. Ya existe otro tamaño registrado con el mismo Nombre.
A33: public | B33: actualizarTamano | C33: no static | D33: no final | E33: Permite modificar el nombre de un tamaño que ya existe. | F33: tamano | G33: Otro | H33: Tamano | I33: Por valor | J33: no final | K33: Identificador del tamaño que se desea modificar, junto con el nuevo nombre. | L33: Otro | M33: Tamano | N33: El tamaño no existe en el sistema. El nuevo dato ingresado no es válido según el tipo de dato, la obligatoriedad o el formato esperado.
A34: public | B34: eliminarTamano | C34: no static | D34: no final | E34: Permite eliminar un tamaño que no tenga productos asociados que deban conservarse. | F34: id | G34: Otro | H34: UUID | I34: Por valor | J34: no final | K34: Identificador del tamaño que se desea eliminar. | L34: void | N34: El tamaño tiene productos asociados que deben conservarse. El tamaño no existe en el sistema.
A36: Builder (clase interna public static)
A37: Modificador de acceso | B37: Nombre | C37: Tipo acceso método | D37: Tipo modificación método | E37: Descripción | F37: Parámetros | L37: Tipo dato de retorno | N37: Excepciones
F38: Nombre | G38: Tipo de dato | H38: ¿Cuál? | I38: Tipo parámetro | J38: Tipo modificación atributo | K38: Descripción | L38: Tipo de dato | M38: ¿Cuál?
A39: public | B39: Builder | C39: no static | D39: no final | E39: Constructor del Builder: asigna a cada atributo su valor por defecto.
A40: public | B40: id | C40: no static | D40: no final | E40: Asigna el identificador recibido; si es nulo, asigna el identificador por defecto (00000000-0000-0000-0000-000000000000). | F40: id | G40: Otro | H40: UUID | I40: Por valor | J40: no final | K40: Valor que se desea asignar al atributo id. | L40: Otro | M40: Builder
A41: public | B41: tamano | C41: no static | D41: no final | E41: Asigna el texto recibido sin espacios en blanco al inicio y al final, con la primera letra en mayúscula y el resto en minúscula; si es nulo o vacío, asigna una cadena vacía. | F41: tamano | G41: String | I41: Por valor | J41: no final | K41: Valor que se desea asignar al atributo tamano. | L41: Otro | M41: Builder
A42: public | B42: build | C42: no static | D42: no final | E42: Crea la instancia de Tamano con los valores reunidos en el Builder, usando su constructor privado. | L42: Otro | M42: Tamano

Sheet Proveedor
A1: <-Volver al inicio
A2: =Clases!$A$1 -> Clase | B2: =Clases!A8 -> Proveedor
A3: =Clases!$B$1 -> Estereotipo | B3: =Clases!B8 -> class
A4: =Clases!$C$1 -> Descripción | B4: =Clases!C8 -> Representa a las personas o empresas que suministran a la pizzería los insumos y productos necesarios para su operación.
A5: Modificador acceso: | B5: public
A6: Tipo clase: | B6: no final
A7: Relaciones
A8: Relación | B8: Tipo relación | E8: Estructura
A9: Es usada por | B9: Asociación | E9: Compra
A11: Atributos
A12: Modificador de acceso | B12: Nombre | C12: Tipo de dato | E12: Tipo modificación atributo | F12: Tipo acceso atributo | G12: Valor por defecto | J12: Descripción atributo
C13: Tipo de dato | D13: ¿Cuál?
A14: private | B14: id | C14: Otro | D14: UUID | E14: no final | F14: no static | G14: 00000000-0000-0000-0000-000000000000 | J14: Identificador único del proveedor.
A15: private | B15: nombreEmpresa | C15: String | E15: no final | F15: no static | G15: "" (cadena vacía) | J15: Nombre de la empresa a la que pertenece el proveedor.
A16: private | B16: nit | C16: String | E16: no final | F16: no static | G16: "" (cadena vacía) | J16: Número de identificación tributaria (NIT) del proveedor; no se puede repetir entre proveedores.
A17: private | B17: contacto | C17: String | E17: no final | F17: no static | G17: "" (cadena vacía) | J17: Forma de comunicación directa con el proveedor.
A18: private | B18: activo | C18: boolean/Boolean | E18: no final | F18: no static | G18: true | J18: Indica si el proveedor está activo y disponible para nuevas compras.
A20: Constructores
A21: Modificador de acceso | B21: Nombre | C21: Tipo constructor | D21: Descripción | E21: Parámetros | M21: Excepciones
E22: Nombre | F22: Tipo de dato | G22: ¿Cuál? | H22: Tipo parámetro | I22: Tipo modificación atributo | J22: Descripción
A23: private | B23: =B2 -> Proveedor | C23: Parametrizado | D23: Constructor privado: crea la instancia de Proveedor copiando los valores ya saneados que reunió el Builder. Solo se invoca desde Builder.build(). | E23: builder | F23: Otro | G23: Builder | H23: Por valor | I23: no final | J23: Builder con los valores de los atributos de la clase.
A25: Métodos accesores
A26: Modificador de acceso | B26: Nombre | C26: Tipo método accesor | D26: Tipo modificación método | E26: Descripción | F26: Parámetros | L26: Tipo dato de retorno | N26: Excepciones
F27: Nombre | G27: Tipo de dato | H27: ¿Cuál? | I27: Tipo parámetro | J27: Tipo modificación atributo | K27: Descripción | L27: Tipo de dato | M27: ¿Cuál?
A28: public | B28: getId | C28: getter | D28: no final | E28: Método encargado de obtener el valor del atributo id. | L28: Otro | M28: UUID
A29: public | B29: getNombreEmpresa | C29: getter | D29: no final | E29: Método encargado de obtener el valor del atributo nombreEmpresa. | L29: String
A30: public | B30: getNit | C30: getter | D30: no final | E30: Método encargado de obtener el valor del atributo nit. | L30: String
A31: public | B31: getContacto | C31: getter | D31: no final | E31: Método encargado de obtener el valor del atributo contacto. | L31: String
A32: public | B32: isActivo | C32: getter | D32: no final | E32: Método encargado de obtener el valor del atributo activo. | L32: boolean/Boolean
A34: Métodos
A35: Modificador de acceso | B35: Nombre | C35: Tipo acceso método | D35: Tipo modificación método | E35: Descripción | F35: Parámetros | L35: Tipo dato de retorno | N35: Excepciones
F36: Nombre | G36: Tipo de dato | H36: ¿Cuál? | I36: Tipo parámetro | J36: Tipo modificación atributo | K36: Descripción | L36: Tipo de dato | M36: ¿Cuál?
A37: public | B37: registrarProveedor | C37: no static | D37: no final | E37: Permite incorporar un nuevo proveedor al sistema. | F37: proveedor | G37: Otro | H37: Proveedor | I37: Por valor | J37: no final | K37: Información necesaria para registrar e identificar al proveedor. | L37: Otro | M37: Proveedor | N37: Los datos ingresados para registrar el proveedor no son válidos. El identificador generado ya está siendo utilizado por otro proveedor. Ya existe otro proveedor registrado con el mismo NIT. Ya existe otro proveedor registrado con el mismo nombre de empresa.
A38: public | B38: modificarProveedor | C38: no static | D38: no final | E38: Actualizar la información de un proveedor existente sin afectar la trazabilidad de las compras históricas asociadas a este. | F38: proveedor | G38: Otro | H38: Proveedor | I38: Por valor | J38: no final | K38: Identificador del proveedor y datos que se desean modificar. | L38: Otro | M38: Proveedor | N38: El proveedor que se desea actualizar no existe. Los nuevos datos del proveedor no son válidos. La información modificada genera duplicidad con otro proveedor registrado.
A39: public | B39: retirarProveedor | C39: no static | D39: no final | E39: Permite retirar un proveedor con el que la pizzería ya no trabaja: queda inactivo y no se puede usar en nuevas compras, pero se conservan sus compras. | F39: id | G39: Otro | H39: UUID | I39: Por valor | J39: no final | K39: Identificador del proveedor que se desea retirar. | L39: Otro | M39: Proveedor | N39: El proveedor que se desea retirar no existe. El proveedor ya se encuentra retirado. El proveedor tiene compras registradas.
A40: public | B40: consultarProveedoresActivos | C40: static | D40: final | E40: Permite consultar los proveedores activos, ordenados por nombre de empresa, para seleccionarlos al registrar una compra. | L40: Otro | M40: List<Proveedor> | N40: No existen proveedores activos.
A42: Builder (clase interna public static)
A43: Modificador de acceso | B43: Nombre | C43: Tipo acceso método | D43: Tipo modificación método | E43: Descripción | F43: Parámetros | L43: Tipo dato de retorno | N43: Excepciones
F44: Nombre | G44: Tipo de dato | H44: ¿Cuál? | I44: Tipo parámetro | J44: Tipo modificación atributo | K44: Descripción | L44: Tipo de dato | M44: ¿Cuál?
A45: public | B45: Builder | C45: no static | D45: no final | E45: Constructor del Builder: asigna a cada atributo su valor por defecto.
...

Sheet ProductoInterno
A1: <-Volver al inicio
A2: =Clases!$A$1 -> Clase | B2: =Clases!A9 -> ProductoInterno
A3: =Clases!$B$1 -> Estereotipo | B3: =Clases!B9 -> class
A4: =Clases!$C$1 -> Descripción | B4: =Clases!C9 -> Representa cada insumo o producto que la pizzería compra y almacena en su inventario, ya sea que se consuma dentro de una receta o se venda directamente al cliente.
A5: Modificador acceso: | B5: public
A6: Tipo clase: | B6: no final
A7: Relaciones
A8: Relación | B8: Tipo relación | E8: Estructura
A9: Necesita de | B9: Asociación | E9: UnidadMedida
A10: Es usada por | B10: Asociación | E10: Producto
A11: Es usada por | B11: Asociación | E11: DetalleReceta
A12: Es usada por | B12: Asociación | E12: Inventario
A13: Es usada por | B13: Asociación | E13: Lote
A14: Es usada por | B14: Asociación | E14: DetalleCompra
A15: Es usada por | B15: Asociación | E15: ConsumoVenta
A16: Es usada por | B16: Asociación | E16: Cambio
A18: Atributos
A19: Modificador de acceso | B19: Nombre | C19: Tipo de dato | E19: Tipo modificación atributo | F19: Tipo acceso atributo | G19: Valor por defecto | J19: Descripción atributo
C20: Tipo de dato | D20: ¿Cuál?
A21: private | B21: id | C21: Otro | D21: UUID | E21: no final | F21: no static | G21: 00000000-0000-0000-0000-000000000000 | J21: Identificador único del producto interno.
A22: private | B22: nombre | C22: String | E22: no final | F22: no static | G22: "" (cadena vacía) | J22: Nombre del producto interno (ingrediente o bebida almacenada).
A23: private | B23: perecedero | C23: boolean/Boolean | E23: no final | F23: no static | G23: false | J23: Indica si el producto interno es perecedero.
A24: private | B24: vidaUtil | C24: int/Integer | E24: no final | F24: no static | G24: 0 | J24: Vida útil del producto interno en días: de 1 a 400 si es perecedero y 0 si no lo es.
A25: private | B25: tipoMedida | C25: Otro | D25: UnidadMedida | E25: no final | F25: no static | G25: Instancia por defecto de UnidadMedida | J25: Unidad de medida en la que se maneja el producto interno; su tipo (Peso, Volumen o Unidad) define la unidad de las recetas.
A26: private | B26: activo | C26: boolean/Boolean | E26: no final | F26: no static | G26: true | J26: Indica si el producto interno está activo y disponible para usarse en recetas y compras.
A28: Constructores
A29: Modificador de acceso | B29: Nombre | C29: Tipo constructor | D29: Descripción | E29: Parámetros | M29: Excepciones
E30: Nombre | F30: Tipo de dato | G30: ¿Cuál? | H30: Tipo parámetro | I30: Tipo modificación atributo | J30: Descripción
A31: private | B31: =B2 -> ProductoInterno | C31: Parametrizado | D31: Constructor privado: crea la instancia de ProductoInterno copiando los valores ya saneados que reunió el Builder. Solo se invoca desde Builder.build(). | E31: builder | F31: Otro | G31: Builder | H31: Por valor | I31: no final | J31: Builder con los valores de los atributos de la clase.
A33: Métodos accesores
A34: Modificador de acceso | B34: Nombre | C34: Tipo método accesor | D34: Tipo modificación método | E34: Descripción | F34: Parámetros | L34: Tipo dato de retorno | N34: Excepciones
F35: Nombre | G35: Tipo de dato | H35: ¿Cuál? | I35: Tipo parámetro | J35: Tipo modificación atributo | K35: Descripción | L35: Tipo de dato | M35: ¿Cuál?
A36: public | B36: getId | C36: getter | D36: no final | E36: Método encargado de obtener el valor del atributo id. | L36: Otro | M36: UUID
A37: public | B37: getNombre | C37: getter | D37: no final | E37: Método encargado de obtener el valor del atributo nombre. | L37: String
A38: public | B38: isPerecedero | C38: getter | D38: no final | E38: Método encargado de obtener el valor del atributo perecedero. | L38: boolean/Boolean
A39: public | B39: getVidaUtil | C39: getter | D39: no final | E39: Método encargado de obtener el valor del atributo vidaUtil. | L39: int/Integer
A40: public | B40: getTipoMedida | C40: getter | D40: no final | E40: Método encargado de obtener el valor del atributo tipoMedida. | L40: Otro | M40: UnidadMedida
A41: public | B41: isActivo | C41: getter | D41: no final | E41: Método encargado de obtener el valor del atributo activo. | L41: boolean/Boolean
A43: Métodos
A44: Modificador de acceso | B44: Nombre | C44: Tipo acceso método | D44: Tipo modificación método | E44: Descripción | F44: Parámetros | L44: Tipo dato de retorno | N44: Excepciones
...

Sheet Producto
A1: <-Volver al inicio
A2: =Clases!$A$1 -> Clase | B2: =Clases!A10 -> Producto
A3: =Clases!$B$1 -> Estereotipo | B3: =Clases!B10 -> class
A4: =Clases!$C$1 -> Descripción | B4: =Clases!C10 -> Representa los artículos que la pizzería comercializa y que pueden ser vendidos al cliente, sirviendo como referencia para identificar y gestionar su oferta comercial.
A5: Modificador acceso: | B5: public
A6: Tipo clase: | B6: no final
A7: Relaciones
A8: Relación | B8: Tipo relación | E8: Estructura
A9: Necesita de | B9: Asociación | E9: TipoProducto
A10: Necesita de | B10: Asociación | E10: Tamano
A11: Necesita de | B11: Asociación | E11: ProductoInterno
A12: Es usada por | B12: Composición | E12: DetalleReceta
A13: Es usada por | B13: Asociación | E13: DetalleVenta
A14: Es usada por | B14: Asociación | E14: HistoricoPrecio
A16: Atributos
A17: Modificador de acceso | B17: Nombre | C17: Tipo de dato | E17: Tipo modificación atributo | F17: Tipo acceso atributo | G17: Valor por defecto | J17: Descripción atributo
C18: Tipo de dato | D18: ¿Cuál?
A19: private | B19: id | C19: Otro | D19: UUID | E19: no final | F19: no static | G19: 00000000-0000-0000-0000-000000000000 | J19: Identificador único del producto.
A20: private | B20: nombre | C20: String | E20: no final | F20: no static | G20: "" (cadena vacía) | J20: Nombre del producto que ofrece la pizzería.
A21: private | B21: tipoProducto | C21: Otro | D21: TipoProducto | E21: no final | F21: no static | G21: Instancia por defecto de TipoProducto | J21: Clasificación a la que pertenece el producto (Pizza, Bebida o Adición).
A22: private | B22: tamano | C22: Otro | D22: Tamano | E22: no final | F22: no static | G22: Instancia por defecto de Tamano | J22: Presentación de tamaño del producto; los productos que no son pizza usan "No aplica".
A23: private | B23: productoInterno | C23: boolean/Boolean | E23: no final | F23: no static | G23: false | J23: Indica si el producto se vende directamente desde el inventario, sin necesidad de receta.
A24: private | B24: productoInternoAsociado | C24: Otro | D24: ProductoInterno | E24: no final | F24: no static | G24: Instancia por defecto de ProductoInterno | J24: Producto interno asociado: si el producto se vende directamente desde el inventario es el producto interno con el mismo nombre; si no, es el registro "Sin insumo".
A25: private | B25: precio | C25: Otro | D25: BigDecimal | E25: no final | F25: no static | G25: 0 | J25: Precio de venta al público del producto; coincide con el precio vigente en el histórico de precios.
A26: private | B26: activo | C26: boolean/Boolean | E26: no final | F26: no static | G26: true | J26: Indica si el producto está activo y disponible para la venta.
A28: Constructores
A29: Modificador de acceso | B29: Nombre | C29: Tipo constructor | D29: Descripción | E29: Parámetros | M29: Excepciones
E30: Nombre | F30: Tipo de dato | G30: ¿Cuál? | H30: Tipo parámetro | I30: Tipo modificación atributo | J30: Descripción
A31: private | B31: =B2 -> Producto | C31: Parametrizado | D31: Constructor privado: crea la instancia de Producto copiando los valores ya saneados que reunió el Builder. Solo se invoca desde Builder.build(). | E31: builder | F31: Otro | G31: Builder | H31: Por valor | I31: no final | J31: Builder con los valores de los atributos de la clase.
A33: Métodos accesores
A34: Modificador de acceso | B34: Nombre | C34: Tipo método accesor | D34: Tipo modificación método | E34: Descripción | F34: Parámetros | L34: Tipo dato de retorno | N34: Excepciones
F35: Nombre | G35: Tipo de dato | H35: ¿Cuál? | I35: Tipo parámetro | J35: Tipo modificación atributo | K35: Descripción | L35: Tipo de dato | M35: ¿Cuál?
A36: public | B36: getId | C36: getter | D36: no final | E36: Método encargado de obtener el valor del atributo id. | L36: Otro | M36: UUID
A37: public | B37: getNombre | C37: getter | D37: no final | E37: Método encargado de obtener el valor del atributo nombre. | L37: String
A38: public | B38: getTipoProducto | C38: getter | D38: no final | E38: Método encargado de obtener el valor del atributo tipoProducto. | L38: Otro | M38: TipoProducto
A39: public | B39: getTamano | C39: getter | D39: no final | E39: Método encargado de obtener el valor del atributo tamano. | L39: Otro | M39: Tamano
A40: public | B40: isProductoInterno | C40: getter | D40: no final | E40: Método encargado de obtener el valor del atributo productoInterno. | L40: boolean/Boolean
A41: public | B41: getProductoInternoAsociado | C41: getter | D41: no final | E41: Método encargado de obtener el valor del atributo productoInternoAsociado. | L41: Otro | M41: ProductoInterno
A42: public | B42: getPrecio | C42: getter | D42: no final | E42: Método encargado de obtener el valor del atributo precio. | L42: Otro | M42: BigDecimal
A43: public | B43: isActivo | C43: getter | D43: no final | E43: Método encargado de obtener el valor del atributo activo. | L43: boolean/Boolean
...

Sheet DetalleReceta
A1: <-Volver al inicio
A2: =Clases!$A$1 -> Clase | B2: =Clases!A11 -> DetalleReceta
A3: =Clases!$B$1 -> Estereotipo | B3: =Clases!B11 -> class
A4: =Clases!$C$1 -> Descripción | B4: =Clases!C11 -> Representa cada uno de los ingredientes necesarios para elaborar una receta, indicando la cantidad requerida y la unidad de medida utilizada.
A5: Modificador acceso: | B5: public
A6: Tipo clase: | B6: no final
A7: Relaciones
A8: Relación | B8: Tipo relación | E8: Estructura
A9: Necesita de | B9: Asociación | E9: ProductoInterno
A10: Necesita de | B10: Asociación | E10: UnidadMedida
A11: Necesita de | B11: Composición | E11: Producto
A13: Atributos
A14: Modificador de acceso | B14: Nombre | C14: Tipo de dato | E14: Tipo modificación atributo | F14: Tipo acceso atributo | G14: Valor por defecto | J14: Descripción atributo
C15: Tipo de dato | D15: ¿Cuál?
A16: private | B16: id | C16: Otro | D16: UUID | E16: no final | F16: no static | G16: 00000000-0000-0000-0000-000000000000 | J16: Identificador único del detalle de receta.
A17: private | B17: productoInterno | C17: Otro | D17: ProductoInterno | E17: no final | F17: no static | G17: Instancia por defecto de ProductoInterno | J17: Producto interno (ingrediente) que se utiliza en la receta.
A18: private | B18: cantidad | C18: Otro | D18: BigDecimal | E18: no final | F18: no static | G18: 0 | J18: Cantidad requerida del ingrediente para elaborar el producto.
A19: private | B19: unidadMedida | C19: Otro | D19: UnidadMedida | E19: no final | F19: no static | G19: Instancia por defecto de UnidadMedida | J19: Unidad de medida de la cantidad del ingrediente; se asigna automáticamente según el tipo de medida del producto interno (g, ml o und).
A20: private | B20: producto | C20: Otro | D20: Producto | E20: no final | F20: no static | G20: Instancia por defecto de Producto | J20: Producto (pizza o adición) al que pertenece esta línea de receta.
A22: Constructores
A23: Modificador de acceso | B23: Nombre | C23: Tipo constructor | D23: Descripción | E23: Parámetros | M23: Excepciones
E24: Nombre | F24: Tipo de dato | G24: ¿Cuál? | H24: Tipo parámetro | I24: Tipo modificación atributo | J24: Descripción
A25: private | B25: =B2 -> DetalleReceta | C25: Parametrizado | D25: Constructor privado: crea la instancia de DetalleReceta copiando los valores ya saneados que reunió el Builder. Solo se invoca desde Builder.build(). | E25: builder | F25: Otro | G25: Builder | H25: Por valor | I25: no final | J25: Builder con los valores de los atributos de la clase.
A27: Métodos accesores
A28: Modificador de acceso | B28: Nombre | C28: Tipo método accesor | D28: Tipo modificación método | E28: Descripción | F28: Parámetros | L28: Tipo dato de retorno | N28: Excepciones
F29: Nombre | G29: Tipo de dato | H29: ¿Cuál? | I29: Tipo parámetro | J29: Tipo modificación atributo | K29: Descripción | L29: Tipo de dato | M29: ¿Cuál?
A30: public | B30: getId | C30: getter | D30: no final | E30: Método encargado de obtener el valor del atributo id. | L30: Otro | M30: UUID
A31: public | B31: getProductoInterno | C31: getter | D31: no final | E31: Método encargado de obtener el valor del atributo productoInterno. | L31: Otro | M31: ProductoInterno
A32: public | B32: getCantidad | C32: getter | D32: no final | E32: Método encargado de obtener el valor del atributo cantidad. | L32: Otro | M32: BigDecimal
A33: public | B33: getUnidadMedida | C33: getter | D33: no final | E33: Método encargado de obtener el valor del atributo unidadMedida. | L33: Otro | M33: UnidadMedida
A34: public | B34: getProducto | C34: getter | D34: no final | E34: Método encargado de obtener el valor del atributo producto. | L34: Otro | M34: Producto
A36: Métodos
A37: Modificador de acceso | B37: Nombre | C37: Tipo acceso método | D37: Tipo modificación método | E37: Descripción | F37: Parámetros | L37: Tipo dato de retorno | N37: Excepciones
F38: Nombre | G38: Tipo de dato | H38: ¿Cuál? | I38: Tipo parámetro | J38: Tipo modificación atributo | K38: Descripción | L38: Tipo de dato | M38: ¿Cuál?
A39: public | B39: agregarIngredienteAReceta | C39: no static | D39: no final | E39: Permite incorporar un ingrediente a la composición de una receta indicando la cantidad necesaria para su elaboración. | F39: detalleReceta | G39: Otro | H39: DetalleReceta | I39: Por valor | J39: no final | K39: Información necesaria para incorporar el ingrediente a la receta. | L39: Otro | M39: DetalleReceta | N39: Los datos ingresados para registrar el detalle de receta no son válidos. El producto (pizza o adición) al que pertenece el detalle de receta no existe. El producto se encuentra inactivo. El producto asociado al detalle de receta no es una pizza ni una adición. El producto interno que se quiere asociar al detalle de receta no existe. El producto interno se encuentra inactivo. La cantidad no es mayor que cero o supera 10.000. No fue posible determinar la unidad de medida a partir del producto interno. El producto interno ya se encuentra registrado dentro de la misma receta. El identificador generado ya está siendo utilizado.
A40: public | B40: modificarCantidadDeIngrediente | C40: no static | D40: no final | E40: Permite ajustar la cantidad de un ingrediente requerida para la elaboración de una receta. | F40: detalleReceta | G40: Otro | H40: DetalleReceta | I40: Por valor | J40: no final | K40: Identificador del detalle y nueva información necesaria para modificar la cantidad. | L40: Otro | M40: DetalleReceta | N40: El detalle de receta que se desea actualizar no existe. La nueva cantidad no es mayor que cero o supera 10.000.
A41: public | B41: retirarIngredienteDeReceta | C41: no static | D41: no final | E41: Permite retirar un ingrediente de la composición de una receta cuando deja de ser requerido para su elaboración. | F41: id | G41: Otro | H41: UUID | I41: Por valor | J41: no final | K41: Identificador del detalle de receta que se desea retirar. | L41: void | N41: El detalle de receta no existe con el identificador indicado.
A42: public | B42: consultarIngredientesPorFiltro | C42: static | D42: final | E42: Permite consultar los ingredientes de recetas que cumplan con los criterios indicados, por ejemplo todos los ingredientes de un producto. | F42: filtro | G42: Otro | H42: DetalleReceta | I42: Por valor | J42: no final | K42: Criterios de búsqueda. | L42: Otro | M42: List<DetalleReceta> | N42: No existen ingredientes que cumplan con el filtro.
A43: public | B43: consultarRecetasDeProductosActivos | C43: static | D43: final | E43: Permite consultar las recetas (ingredientes) de los productos que la pizzería ofrece actualmente. | L43: Otro | M43: List<DetalleReceta> | N43: No existen recetas de productos activos.
A44: public | B44: consultarRecetasDeProductosInactivos | C44: static | D44: final | E44: Permite consultar las recetas de los productos que la pizzería ya no ofrece, para conservar su historial. | L44: Otro | M44: List<DetalleReceta> | N44: No existen recetas de productos inactivos.
...

Sheet Inventario
A1: <-Volver al inicio
A2: =Clases!$A$1 -> Clase | B2: =Clases!A12 -> Inventario
A3: =Clases!$B$1 -> Estereotipo | B3: =Clases!B12 -> class
A4: =Clases!$C$1 -> Descripción | B4: =Clases!C12 -> Representa las existencias disponibles de los insumos y productos que la pizzería necesita para operar y atender sus ventas.
A5: Modificador acceso: | B5: public
A6: Tipo clase: | B6: no final
A7: Relaciones
A8: Relación | B8: Tipo relación | E8: Estructura
A9: Necesita de | B9: Asociación | E9: ProductoInterno
A10: Necesita de | B10: Asociación | E10: UnidadMedida
A12: Atributos
A13: Modificador de acceso | B13: Nombre | C13: Tipo de dato | E13: Tipo modificación atributo | F13: Tipo acceso atributo | G13: Valor por defecto | J13: Descripción atributo
C14: Tipo de dato | D14: ¿Cuál?
A15: private | B15: id | C15: Otro | D15: UUID | E15: no final | F15: no static | G15: 00000000-0000-0000-0000-000000000000 | J15: Identificador único del registro de inventario.
A16: private | B16: cantidadTotal | C16: Otro | D16: BigDecimal | E16: no final | F16: no static | G16: 0 | J16: Cantidad total disponible del producto interno, expresada en su unidad de medida de inventario.
A17: private | B17: productoInterno | C17: Otro | D17: ProductoInterno | E17: no final | F17: no static | G17: Instancia por defecto de ProductoInterno | J17: Producto interno (ingrediente o bebida) al que corresponde este registro de inventario; cada producto interno tiene un único registro.
A18: private | B18: unidadMedidaInventario | C18: Otro | D18: UnidadMedida | E18: no final | F18: no static | G18: Instancia por defecto de UnidadMedida | J18: Unidad de medida en la que se maneja el inventario (kg, l o und), determinada por el tipo de medida del producto interno.
A19: private | B19: stockMinimo | C19: Otro | D19: BigDecimal | E19: no final | F19: no static | G19: 1 | J19: Cantidad mínima que debe mantenerse disponible antes de requerir reposición.
A21: Constructores
A22: Modificador de acceso | B22: Nombre | C22: Tipo constructor | D22: Descripción | E22: Parámetros | M22: Excepciones
E23: Nombre | F23: Tipo de dato | G23: ¿Cuál? | H23: Tipo parámetro | I23: Tipo modificación atributo | J23: Descripción
A24: private | B24: =B2 -> Inventario | C24: Parametrizado | D24: Constructor privado: crea la instancia de Inventario copiando los valores ya saneados que reunió el Builder. Solo se invoca desde Builder.build(). | E24: builder | F24: Otro | G24: Builder | H24: Por valor | I24: no final | J24: Builder con los valores de los atributos de la clase.
A26: Métodos accesores
A27: Modificador de acceso | B27: Nombre | C27: Tipo método accesor | D27: Tipo modificación método | E27: Descripción | F27: Parámetros | L27: Tipo dato de retorno | N27: Excepciones
