Workbook

Sheet Modelo de dominio
A1: Ir a Objetos de Dominio >>>

Sheet Objetos de dominio
A1: <<<Modelo de Dominio
A2: Nombre | B2: Descripcion | C2: Linea de vida | D2: Muestreo | E2: Caracterizacion | F2: Eventos | G2: Politicas
A3: Proveedor | B3: Son las personas o empresas que le venden a la pizzería los insumos que necesita para funcionar. | C3: 1 | D3: Ir | E3: Ir | F3: Ir | G3: Ir
A4: UnidadMedida | B4: Es la unidad con la que se mide cada ingrediente o producto, por ejemplo kilos, litros o unidades. | C4: 1 | D4: Ir | E4: Ir | F4: Ir | G4: Ir
A5: TipoProducto | B5: Indica en qué categoría entra cada producto que vende la pizzería, por ejemplo si es una pizza, una bebida o una adición. | C5: 1 | D5: Ir | E5: Ir | F5: Ir | G5: Ir
A6: ClaseMovimiento | B6: Indica si un movimiento de inventario fue una entrada o una salida de insumos o productos. | C6: 1 | D6: Ir | E6: Ir | F6: Ir | G6: Ir
A7: Tamaño | B7: Son los distintos tamaños en los que la pizzería puede ofrecer una pizza. | C7: 1 | D7: Ir | E7: Ir | F7: Ir | G7: Ir
A8: CategoriaOrigen | B8: Indica qué operación fue la que generó un movimiento de inventario: una compra, una venta, un cambio de un producto que no es perecedero, o el retiro de un lote (porque se cambió o porque se venció). | C8: 1 | D8: Ir | E8: Ir | F8: Ir | G8: Ir
A9: Usuario | B9: Es la persona que puede ingresar a la aplicacion; solo el administrador de la pizzeria puede iniciar sesion. | C9: 1 | D9: Ir | E9: Ir | F9: Ir | G9: Ir
A10: Compra | B10: Es cuando la pizzería le compra insumos o productos a un proveedor. | C10: 2 | D10: Ir | E10: Ir | F10: Ir | G10: Ir
A11: ProductoInterno | B11: Es cada insumo o producto que la pizzería compra y guarda en su inventario, sin importar si se usa para preparar algo o si se vende directamente al cliente. | C11: 2 | D11: Ir | E11: Ir | F11: Ir | G11: Ir
A12: TipoMovimiento | B12: Es el código de una operación concreta que mueve el inventario (cada detalle de compra, consumo de una venta o cambio tiene el suyo). Pertenece a una CategoriaOrigen y lo comparten la operación y los movimientos que genera. | C12: 2 | D12: Ir | E12: Ir | F12: Ir | G12: Ir
A13: DetalleCompra | B13: Es cada uno de los productos o insumos que se compraron en una compra, con la cantidad de cada uno. | C13: 3 | D13: Ir | E13: Ir | F13: Ir | G13: Ir
A14: Producto | B14: Son los productos que la pizzería vende, como las pizzas, las bebidas y las adiciones. | C14: 4 | D14: Ir | E14: Ir | F14: Ir | G14: Ir
... A24: SalidaLote | B24: SalidaLote representa el retiro efectivo de una cantidad de producto perteneciente a un lote, realizado por el usuario después de atender una alerta de proximidad al vencimiento. Atributos: Id, Lote, Cantidad y FechaMovimiento. Relación: Lote 1 — 0..1 SalidaLote (un lote puede tener como máximo un retiro; cada retiro pertenece a un único lote). La alerta no se almacena aquí: se calcula a partir de Lote.FechaVencimiento. | C24: 7 | D24: Ir | E24: Ir | F24: Ir | G24: Ir
A27: Categorias de colores
A28: Descripciones
A29: Id's
A30: combinacion unica
A31: objeto
A32: Tipo de dato
A33: Si es obligatorio o no el atributo
A34: Calculado

Sheet Reglas de negocio
A1: Cada pizzería administra un inventario independiente.
A2: Todo cambio en las existencias de los productos internos debe quedar registrado: las entradas y salidas por compra, venta y cambio mediante un MovimientoInventario, y los retiros por vencimiento mediante una SalidaLote.
A3: El inventario debe reflejar automáticamente los movimientos y retiros registrados (actualizaciones).
A4: Cada pizza y cada adición posee una única receta. Las bebidas no tienen receta, porque se venden directamente del inventario.
A5: Una venta puede tener muchos productos, cada uno registrado en un DetalleVenta. El total de la venta se calcula como la suma de los subtotales de sus detalles y, con base en él, se emite la factura y se realiza el pago.
A7: Todo se paga de contado, para no manejar sistemas de crédito con los proveedores.
A8: No se maneja nómina: el sistema no registra empleados ni sueldos. Solo existe el usuario Administrador, que es quien ingresa a la aplicación.
A9: El precio de un producto puede cambiarse cuando sea necesario; cada cambio queda registrado en HistoricoPrecio.
A10: Cada instancia del sistema corresponde a una sola pizzería, y la información operativa pertenece exclusivamente a la pizzería que utiliza dicha instancia.
A11: El valor total de una compra corresponde a la suma de los precios de compra de todos sus detalles de compra, y no puede superar 5.000.000.
A12: Solo los usuarios activos con rol Administrador pueden ingresar a la aplicación.
A13: La unidad de medida de cada ingrediente de una receta se asigna automáticamente según el tipo de medida del producto interno: Peso = g, Volumen = ml, Unidad = und.
... A23: Cuando un lote está próximo a vencer: si el producto es no perecedero se cambia con el proveedor (Cambio); si es perecedero no se cambia, se retira del lote con una SalidaLote.

Sheet M-Proveedor
A1: <<<Modelo de Dominio | B1: <<<Objetos de Dominio
A2: Identificador unico del proveedor dentro de la pizzeria | B2: Nombre de la empresa a la que pertenece el proveedor | C2: Numero de identificacion tributaria (NIT) del proveedor; no se puede repetir entre proveedores | D2: Forma de comunicacion directa con el proveedor | E2: Indica si el proveedor esta activo y disponible para nuevas compras
A3: Tipo de dato | B3: Alfanumerico(max 60 caracteres) | C3: Alfanumerico(max 15 caracteres) | D3: Alfanumerico(max 10 caracteres) | E3: Tipo Logico
A4: Obligatorio | B4: Si | C4: Si | D4: Si | E4: Si
A5: Id | B5: Nombre Empresa | C5: NIT | D5: Contacto | E5: Activo | F5: Combinacion unica 1 | G5: Combinacion unica 2
A6: 1 | B6: Colanta | C6: 900100001-1 | D6: 3053086510 | E6: Si | F6: =B6 -> Colanta | G6: =C6 -> 900100001-1
A7: 2 | B7: Harinera del valle | C7: 900100002-2 | D7: 3139562216 | E7: Si | F7: =B7 -> Harinera del valle | G7: =C7 -> 900100002-2
A8: 3 | B8: Postobon | C8: 900100003-3 | D8: 3108582230 | E8: Si | F8: =B8 -> Postobon | G8: =C8 -> 900100003-3
A9: 4 | B9: Central de Abastos | C9: 900100004-4 | D9: 3201234567 | E9: Si | F9: =B9 -> Central de Abastos | G9: =C9 -> 900100004-4

Sheet C-Proveedor
A1: <<<Modelo de Dominio | B1: <<<Objetos de Dominio
A2: Nombre | B2: Proveedor
A3: Descripción | B3: =HYPERLINK("#'Objetos de dominio'!B3", 'Objetos de dominio'!B3) -> Son las personas o empresas que le venden a la pizzería los insumos que necesita para funcionar.
A4: Nombre atributo | B4: Descripción atributo | C4: Identificador del objeto de dominio | D4: Tipo de dato | E4: Obligatorio | F4: Longitud mínima (si aplica) | G4: Longitud máxima (si aplica) | H4: Precisión (si aplica) | I4: Rendondeo (si aplica) | J4: Rango inicial (si aplica) | K4: Rango final (si aplica) | L4: Formato (si aplica) | M4: Reglas especiales (si aplica) | N4: Dato calculado | O4: Aplica ajuste del dato (si aplica) | P4: Carácter de ajuste (si aplica) | Q4: Quitar espacios en blanco al inicio (si aplica) | R4: Quitar espacios en blanco al fin (si aplica) | S4: Dato sensible (si aplica) | T4: Valor por defecto (si aplica) | U4: Auto generado | V4: =HYPERLINK("#'C-Proveedor'!A18", 'C-Proveedor'!A18) -> Registrar proveedor | W4: =HYPERLINK("#'C-Proveedor'!A22", 'C-Proveedor'!A22) -> Modificar proveedor | Y4: =HYPERLINK("#'C-Proveedor'!A25", 'C-Proveedor'!A25) -> Retirar proveedor | Z4: =HYPERLINK("#'C-Proveedor'!A28", 'C-Proveedor'!A28) -> Consultar proveedores activos
A5: =HYPERLINK("#'M-Proveedor'!A5", 'M-Proveedor'!A5) -> Id | B5: =HYPERLINK("#'M-Proveedor'!A2", 'M-Proveedor'!A2) -> Identificador unico del proveedor dentro de la pizzeria | C5: Si | D5: Identificador universal | E5: Si | N5: No | O5: No | Q5: No | R5: No | S5: No | U5: Si | V5: Requerido | W5: Requerido | X5: No Modificable | Y5: Requerido | Z5: No Mostrar
A6: =HYPERLINK("#'M-Proveedor'!B5", 'M-Proveedor'!B5) -> Nombre Empresa | B6: =HYPERLINK("#'M-Proveedor'!B2", 'M-Proveedor'!B2) -> Nombre de la empresa a la que pertenece el proveedor | C6: No | D6: Alfanumerico | E6: Si | F6: 1 | G6: 60 | M6: Se debe asegurar una sanitización del dato | N6: No | O6: No | Q6: Si | R6: Si | S6: No | U6: No | V6: Requerido | W6: No Requerido | X6: Modificable | Y6: No Requerido | Z6: Mostrar
A7: =HYPERLINK("#'M-Proveedor'!C5", 'M-Proveedor'!C5) -> NIT | B7: =HYPERLINK("#'M-Proveedor'!C2", 'M-Proveedor'!C2) -> Numero de identificacion tributaria (NIT) del proveedor; no se puede repetir entre proveedores | C7: No | D7: Alfanumerico | E7: Si | F7: 1 | G7: 15 | M7: No puede existir otro proveedor con el mismo NIT. Se debe asegurar una sanitizacion del dato. | N7: No | O7: No | Q7: Si | R7: Si | S7: No | U7: No | V7: Requerido | W7: No Requerido | X7: Modificable | Y7: No Requerido | Z7: Mostrar
A8: =HYPERLINK("#'M-Proveedor'!D5", 'M-Proveedor'!D5) -> Contacto | B8: =HYPERLINK("#'M-Proveedor'!D2", 'M-Proveedor'!D2) -> Forma de comunicacion directa con el proveedor | C8: No | D8: Alfanumerico | E8: Si | F8: 1 | G8: 10 | M8: Se debe asegurar una sanitizacion del dato | N8: No | O8: No | Q8: Si | R8: Si | S8: No | U8: No | V8: Requerido | W8: No Requerido | X8: Modificable | Y8: No Requerido | Z8: Mostrar
A9: =HYPERLINK("#'M-Proveedor'!E5", 'M-Proveedor'!E5) -> Activo | B9: =HYPERLINK("#'M-Proveedor'!E2", 'M-Proveedor'!E2) -> Indica si el proveedor esta activo y disponible para nuevas compras | C9: No | D9: Tipo Logico | E9: Si | M9: Se registra como activo (Si). Al retirar el proveedor pasa a No y ya no puede usarse en nuevas compras. | N9: No | O9: No | Q9: No | R9: No | S9: No | T9: Si | U9: No | V9: No Requerido | W9: No Requerido | X9: No Modificable | Y9: No Requerido | Z9: No Mostrar
A12: Nombre combinación única | B12: Descripción | C12: Atributos involucrados
A13: Combinación única 1 | B13: No puede existir otro proveedor con el mismo nombre de empresa | C13: =HYPERLINK("#'C-Proveedor'!A6", 'C-Proveedor'!A6) -> Nombre Empresa
A14: Combinación única 2 | B14: No pueden existir dos proveedores con el mismo NIT. | C14: =HYPERLINK("#'C-Proveedor'!A7", 'C-Proveedor'!A7) -> NIT
A16: Responsabilidad | C16: Descripción | G16: Entradas | J16: Salida | O16: Políticas (Reglas de Negocio) | Q16: Excepción
G17: Parámetro | H17: Tipo de dato | I17: Descripción | J17: Tipo de Dato | K17: Descripción | O17: Política | P17: Descripción | Q17: Detalle | R17: ¿Qué hago?
A18: =HYPERLINK("#'C-Proveedor'!V4", 'E-Proveedor'!B7) -> Registrar proveedor | C18: ='E-Proveedor'!C7 -> Permite imcorporar un crear un proveedor | G18: Datos | H18: Proveedor | I18: Información necesaria para registrar e identificar al proveedor. | J18: Proveedor | K18: Proveedor registrado con la información proporcionada. | O18: =HYPERLINK("#'P-Proveedor'!A5", 'P-Proveedor'!A5) -> P-PROV-001 | P18: ='P-Proveedor'!B5 -> Asegurar que los datos requeridos para registrar un proveedor sean válidos de acuerdo con el tipo de dato, obligatoriedad, formato, longitud y rango correspondiente. | Q18: Los datos ingresados para registrar el proveedor no son validos. | R18: Rechazar el registro e informar cual dato no es valido.
O19: =HYPERLINK("#'P-Proveedor'!A6", 'P-Proveedor'!A6) -> P-PROV-002 | P19: ='P-Proveedor'!B6 -> Asegurar que el identificador generado para el proveedor no esté siendo utilizado por otro proveedor. | Q19: El identificador generado ya esta siendo utilizado por otro proveedor. | R19: Generar un nuevo identificador hasta garantizar que no exista.
O20: =HYPERLINK("#'P-Proveedor'!A7", 'P-Proveedor'!A7) -> P-PROV-003 | P20: ='P-Proveedor'!B7 -> Asegurar que no exista otro proveedor registrado con el mismo NIT. | Q20: Ya existe otro proveedor registrado con el mismo NIT. | R20: Rechazar el registro e informar que ya existe un proveedor con ese NIT.
O21: =HYPERLINK("#'P-Proveedor'!A14", 'P-Proveedor'!A14) -> P-PROV-010 | P21: ='P-Proveedor'!B14 -> Asegurar que no exista otro proveedor registrado con el mismo nombre de empresa. | Q21: Ya existe otro proveedor registrado con el mismo nombre de empresa. | R21: Rechazar el registro e informar que ya existe un proveedor con ese nombre.
A22: =HYPERLINK("#'C-Proveedor'!W4", 'E-Proveedor'!B11) -> Modificar proveedor | C22: ='E-Proveedor'!C11 -> Actualizar la información de un proveedor existente sin afectar la trazabilidad de las compras históricas asociadas a este. | G22: Datos | H22: Proveedor | I22: Identificador del proveedor y datos que se desean modificar. | J22: Proveedor | K22: Proveedor actualizado con la información proporcionada. | O22: =HYPERLINK("#'P-Proveedor'!A8", 'P-Proveedor'!A8) -> P-PROV-004 | P22: ='P-Proveedor'!B8 -> Asegurar que el proveedor que se desea actualizar se encuentre registrado en el sistema. | Q22: El proveedor que se desea actualizar no existe. | R22: Rechazar la actualizacion e informar que el proveedor no existe.
O23: =HYPERLINK("#'P-Proveedor'!A5", 'P-Proveedor'!A5) -> P-PROV-001 | P23: ='P-Proveedor'!B5 -> Asegurar que los datos requeridos para registrar un proveedor sean válidos de acuerdo con el tipo de dato, obligatoriedad, formato, longitud y rango correspondiente. | Q23: Los nuevos datos del proveedor no son validos. | R23: Rechazar la modificacion e informar cual dato no es valido.
O24: =HYPERLINK("#'P-Proveedor'!A9", 'P-Proveedor'!A9) -> P-PROV-005 | P24: ='P-Proveedor'!B9 -> Asegurar que la información modificada del proveedor no genere duplicidad con otro proveedor registrado. | Q24: La informacion modificada genera duplicidad con otro proveedor registrado. | R24: Rechazar la actualizacion e informar la duplicidad encontrada.
A25: =HYPERLINK("#'C-Proveedor'!Y4", 'E-Proveedor'!B14) -> Retirar proveedor | C25: ='E-Proveedor'!C14 -> Permite retirar un proveedor con el que la pizzeria ya no trabaja: queda inactivo y no se puede usar en nuevas compras, pero se conservan sus compras. | G25: Id | H25: UUID | I25: Identificador del proveedor que se desea retirar. | J25: Proveedor | K25: Proveedor retirado de acuerdo con las reglas establecidas. | O25: =HYPERLINK("#'P-Proveedor'!A10", 'P-Proveedor'!A10) -> P-PROV-006 | P25: ='P-Proveedor'!B10 -> Asegurar que el proveedor que se desea retirar se encuentre registrado en el sistema. | Q25: El proveedor que se desea retirar no existe. | R25: Rechazar el retiro e informar que el proveedor no existe.
O26: =HYPERLINK("#'P-Proveedor'!A15", 'P-Proveedor'!A15) -> P-PROV-011 | P26: ='P-Proveedor'!B15 -> Asegurar que el proveedor que se desea retirar no se encuentre ya retirado. | Q26: El proveedor ya se encuentra retirado. | R26: Informar que el proveedor ya esta retirado.
O27: =HYPERLINK("#'P-Proveedor'!A11", 'P-Proveedor'!A11) -> P-PROV-007 | P27: ='P-Proveedor'!B11 -> Asegurar que al retirar un proveedor se conserven sus compras registradas: el retiro solo cambia su estado a inactivo y no borra informacion. | Q27: El proveedor tiene compras registradas. | R27: Retirar el proveedor sin borrar sus compras; siguen disponibles para consulta.
A28: =HYPERLINK("#'C-Proveedor'!Z4", 'E-Proveedor'!B17) -> Consultar proveedores activos | C28: ='E-Proveedor'!C17 -> Permite consultar los proveedores activos, ordenados por nombre de empresa, para seleccionarlos al registrar una compra. | G28: Ninguno | I28: No requiere datos de entrada. | J28: Lista de Proveedor | K28: Proveedores activos ordenados por nombre de empresa. | O28: =HYPERLINK("#'P-Proveedor'!A16", 'P-Proveedor'!A16) -> P-PROV-012 | P28: ='P-Proveedor'!B16 -> Asegurar que solo se consulten los proveedores activos, que son los disponibles para registrar nuevas compras. | Q28: No existen proveedores activos. | R28: Informar que no hay proveedores activos disponibles.

Sheet E-Proveedor
A1: <<<Modelo de Dominio | B1: <<<Objetos de Dominio
A2: Objeto de Dominio: | B2: Proveedor
A3: Descripción: | B3: ='C-Proveedor'!B3 -> Son las personas o empresas que le venden a la pizzería los insumos que necesita para funcionar.
A4: Actor | B4: Action/Command | D4: Entity/Aggregate/Object domain | E4: Read Model | G4: Business Rule/Policy | H4: External System | I4: Domain Event | J4: Hotspot/questions/Risk
A5: Actor | B5: Acción | C5: Descripción | D5: Objeto de dominio | E5: Información externa | G5: Políticas | H5: Sistema Externo | I5: Evento | J5: Aspectos por solucionar
E6: Información | F6: Descripción | G6: Número
A7: Administrador | B7: Registrar proveedor | C7: Permite imcorporar un crear un proveedor | D7: Proveedor | E7: Información del proveedor | F7: Datos necesarios para identificar y contactar al proveedor, como nombre de empresa y medio de contacto. | G7: =HYPERLINK("#'P-Proveedor'!A5", "P-PROV-001") -> P-PROV-001 | I7: Proveedor registrado
G8: =HYPERLINK("#'P-Proveedor'!A6", "P-PROV-002") -> P-PROV-002
G9: =HYPERLINK("#'P-Proveedor'!A7", "P-PROV-003") -> P-PROV-003
G10: =HYPERLINK("#'P-Proveedor'!A14", "P-PROV-010") -> P-PROV-010
A11: Administrador | B11: Modificar proveedor | C11: Actualizar la información de un proveedor existente sin afectar la trazabilidad de las compras históricas asociadas a este. | D11: Proveedor | E11: Información del proveedor | F11: Datos actuales y nuevos del proveedor necesarios para identificarlo y realizar la actualización. | G11: =HYPERLINK("#'P-Proveedor'!A8", "P-PROV-004") -> P-PROV-004 | I11: Proveedor modificado
G12: =HYPERLINK("#'P-Proveedor'!A5", "P-PROV-001") -> P-PROV-001
G13: =HYPERLINK("#'P-Proveedor'!A9", "P-PROV-005") -> P-PROV-005
A14: Administrador | B14: Retirar proveedor | C14: Permite retirar un proveedor con el que la pizzeria ya no trabaja: queda inactivo y no se puede usar en nuevas compras, pero se conservan sus compras. | D14: Proveedor | E14: Compras hechas al proveedor | F14: Permite verificar las compras asociadas al proveedor antes de retirarlo y conservar su información histórica. | G14: =HYPERLINK("#'P-Proveedor'!A10", "P-PROV-006") -> P-PROV-006 | I14: Proveedor retirado
G15: =HYPERLINK("#'P-Proveedor'!A15", "P-PROV-011") -> P-PROV-011
G16: =HYPERLINK("#'P-Proveedor'!A11", "P-PROV-007") -> P-PROV-007
A17: Administrador | B17: Consultar proveedores activos | C17: Permite consultar los proveedores activos, ordenados por nombre de empresa, para seleccionarlos al registrar una compra. | E17: Proveedores registrados | F17: Proveedores con estado activo. | G17: =HYPERLINK("#'P-Proveedor'!A16", "P-PROV-012") -> P-PROV-012 | I17: Proveedores activos consultados

Sheet P-Proveedor
A1: <<<Modelo de Dominio | B1: <<<Objetos de Dominio
A2: Objeto de Dominio | B2: Proveedor
A3: Descripcion | B3: ='C-Proveedor'!B3 -> Son las personas o empresas que le venden a la pizzería los insumos que necesita para funcionar.
A4: Numero politica | B4: Descripcion Politica | C4: Objeto Responsable | D4: Regla Referenciada
A5: P-PROV-001 | B5: Asegurar que los datos requeridos para registrar un proveedor sean válidos de acuerdo con el tipo de dato, obligatoriedad, formato, longitud y rango correspondiente. | C5: Proveedor
A6: P-PROV-002 | B6: Asegurar que el identificador generado para el proveedor no esté siendo utilizado por otro proveedor. | C6: Proveedor
A7: P-PROV-003 | B7: Asegurar que no exista otro proveedor registrado con el mismo NIT. | C7: Proveedor
A8: P-PROV-004 | B8: Asegurar que el proveedor que se desea actualizar se encuentre registrado en el sistema. | C8: Proveedor
A9: P-PROV-005 | B9: Asegurar que la información modificada del proveedor no genere duplicidad con otro proveedor registrado. | C9: Proveedor
A10: P-PROV-006 | B10: Asegurar que el proveedor que se desea retirar se encuentre registrado en el sistema. | C10: Proveedor
A11: P-PROV-007 | B11: Asegurar que al retirar un proveedor se conserven sus compras registradas: el retiro solo cambia su estado a inactivo y no borra informacion. | C11: Proveedor
A12: P-PROV-008 | B12: Asegurar que un proveedor retirado o inactivo no pueda ser utilizado para registrar nuevas compras, conservando la información histórica de las compras realizadas. | C12: Proveedor
A13: P-PROV-009 | B13: Asegurar que el proveedor exista con el identificador indicado | C13: Proveedor
A14: P-PROV-010 | B14: Asegurar que no exista otro proveedor registrado con el mismo nombre de empresa. | C14: Proveedor
A15: P-PROV-011 | B15: Asegurar que el proveedor que se desea retirar no se encuentre ya retirado. | C15: Proveedor
A16: P-PROV-012 | B16: Asegurar que solo se consulten los proveedores activos, que son los disponibles para registrar nuevas compras. | C16: Proveedor

Sheet M-UnidadMedida
A1: <<<Modelo de Dominio | B1: <<<Objetos de Dominio
A2: Identificador unico de unidad de medida dentro del sistema | B2: Unidad de medida | C2: Tipo de medida a la que corresponde cada unidad de medida
A3: Tipo de dato | B3: Alfanumerico(max 4 caracteres) | C3: Alfanumerico(max 10 caracteres)
A4: Obligatorio | B4: Si | C4: Si
A5: Id | B5: UnidadMedida | C5: TipoMedida | D5: Combinación única 1
A6: 1 | B6: g | C6: Peso | D6: =B6 -> g
A7: 2 | B7: kg | C7: Peso | D7: =B7 -> kg
A8: 3 | B8: ml | C8: Volumen | D8: =B8 -> ml
A9: 4 | B9: l | C9: Volumen | D9: =B9 -> l
A10: 5 | B10: und | C10: Unidad | D10: =B10 -> und

Sheet C-UnidadMedida
A1: <<<Modelo de Dominio | B1: <<<Objetos de Dominio
A2: Nombre | B2: UnidadMedida
A3: Descripción | B3: =HYPERLINK("#'Objetos de dominio'!B4", 'Objetos de dominio'!B4) -> Es la unidad con la que se mide cada ingrediente o producto, por ejemplo kilos, litros o unidades.
A4: Nombre atributo | B4: Descripción atributo | C4: Identificador del objeto de dominio | D4: Tipo de dato | E4: Obligatorio | F4: Longitud mínima (si aplica) | G4: Longitud máxima (si aplica) | H4: Precisión (si aplica) | I4: Rendondeo (si aplica) | J4: Rango inicial (si aplica) | K4: Rango final (si aplica) | L4: Formato (si aplica) | M4: Reglas especiales (si aplica) | N4: Dato calculado | O4: Aplica ajuste del dato (si aplica) | P4: Carácter de ajuste (si aplica) | Q4: Quitar espacios en blanco al inicio (si aplica) | R4: Quitar espacios en blanco al fin (si aplica) | S4: Dato sensible (si aplica) | T4: Valor por defecto (si aplica) | U4: Auto generado | V4: =HYPERLINK("#'C-UnidadMedida'!A17", 'C-UnidadMedida'!A17) -> Consultar unidades de medida disponibles | W4: =HYPERLINK("#'C-UnidadMedida'!A19", 'C-UnidadMedida'!A19) -> Eliminar unidad de medida
A5: =HYPERLINK("#'M-UnidadMedida'!A5", 'M-UnidadMedida'!A5) -> Id | B5: =HYPERLINK("#'M-UnidadMedida'!A2", 'M-UnidadMedida'!A2) -> Identificador unico de unidad de medida dentro del sistema | C5: Si | D5: Identificador universal | E5: Si | N5: No | O5: No | S5: No | U5: Si | V5: No Mostrar | W5: Requerido
A6: =HYPERLINK("#'M-UnidadMedida'!B5", 'M-UnidadMedida'!B5) -> UnidadMedida | B6: =HYPERLINK("#'M-UnidadMedida'!B2", 'M-UnidadMedida'!B2) -> Unidad de medida | C6: No | D6: Alfanumerico | E6: Si | F6: 1 | G6: 4 | M6: Se debe asegurar una sanitizacion del dato. | N6: No | O6: No | Q6: Si | R6: Si | S6: No | U6: No | V6: Mostrar | W6: No Requerido
A7: =HYPERLINK("#'M-UnidadMedida'!C5", 'M-UnidadMedida'!C5) -> TipoMedida | B7: =HYPERLINK("#'M-UnidadMedida'!C2", 'M-UnidadMedida'!C2) -> Tipo de medida a la que corresponde cada unidad de medida | C7: No | D7: Alfanumerico | E7: Si | F7: 1 | G7: 10 | M7: Solo se permiten los tipos Peso (g, kg), Volumen (ml, l) y Unidad (und). Asi el producto interno queda asociado a una unidad valida para su tipo de medida. | N7: No | O7: No | Q7: Si | R7: Si | S7: No | U7: No | V7: No Mostrar | W7: No Requerido
A10: Nombre combinación única | B10: Descripción | C10: Atributos involucrados
A11: Combinación única 1 | B11: No pueden existir dos unidades de medida con el mismo nombre. | C11: =HYPERLINK("#'C-UnidadMedida'!A6", 'C-UnidadMedida'!A6) -> UnidadMedida
A15: Responsabilidad | C15: Descripción | G15: Entradas | J15: Salida | O15: Políticas (Reglas de Negocio) | Q15: Excepción
G16: Parámetro | H16: Tipo de dato | I16: Descripción | J16: Tipo de Dato | K16: Descripción | O16: Política | P16: Descripción | Q16: Detalle | R16: ¿Qué hago?
A17: =HYPERLINK("#'C-UnidadMedida'!V4", 'E-UnidadMedida'!B7) -> Consultar unidades de medida disponibles | C17: ='E-UnidadMedida'!C7 -> Permite consultar las unidades de medida precargadas en el sistema para seleccionar la unidad adecuada al registrar cantidades de productos, ingredientes, compras, recetas o movimientos de inventario. | G17: Datos | H17: UnidadMedida | I17: Criterios necesarios para realizar la consulta de las unidades de medida disponibles. | J17: Lista de UnidadesMedida | K17: Conjunto de unidades de medida disponibles para selección. | O17: =HYPERLINK("#'P-UnidadMedida'!A5", 'P-UnidadMedida'!A5) -> P-UM-001 | P17: ='P-UnidadMedida'!B5 -> Asegurar que solo se consulten las unidades de medida del catalogo definido por la pizzeria (g, kg, ml, l y und), cada una con su tipo de medida (Peso, Volumen o Unidad). | Q17: No existen unidades de medida registradas en el catalogo. | R17: Informar al administrador que no hay unidades de medida disponibles.
O18: =HYPERLINK("#'P-UnidadMedida'!A6", 'P-UnidadMedida'!A6) -> P-UM-002 | P18: ='P-UnidadMedida'!B6 -> Asegurar que la unidad de medida exista con el identificador indicado | Q18: No existe una unidad de medida asociada al identificador indicado. | R18: Informar que la unidad de medida no existe.
A19: =HYPERLINK("#'C-UnidadMedida'!W4", 'E-UnidadMedida'!B9) -> Eliminar unidad de medida | C19: ='E-UnidadMedida'!C9 -> Permite eliminar una unidad de medida que no este siendo utilizada por ningun otro registro de la pizzeria. | G19: Id | H19: UUID | I19: Identificador de la unidad de medida que se desea eliminar. | J19: UnidadMedida | K19: Unidad de medida eliminada correctamente. | O19: =HYPERLINK("#'P-UnidadMedida'!A7", 'P-UnidadMedida'!A7) -> P-UM-003 | P19: ='P-UnidadMedida'!B7 -> Asegurar que la unidad de medida que se desea eliminar se encuentre registrada en el sistema. | Q19: La unidad de medida que se desea eliminar no existe. | R19: Rechazar la eliminacion e informar que la unidad de medida no existe.
O20: =HYPERLINK("#'P-UnidadMedida'!A8", 'P-UnidadMedida'!A8) -> P-UM-004 | P20: ='P-UnidadMedida'!B8 -> Asegurar que la unidad de medida que se desea eliminar no este siendo utilizada por productos internos, lotes o registros de inventario que requieran conservarla. | Q20: La unidad de medida esta siendo utilizada por un producto interno, un lote o un registro de inventario. | R20: Rechazar la eliminacion e informar en que registros esta en uso la unidad de medida.
O21: =HYPERLINK("#'P-UnidadMedida'!A9", 'P-UnidadMedida'!A9) -> P-UM-005 | P21: ='P-UnidadMedida'!B9 -> Asegurar que la unidad de medida que se desea eliminar no este siendo utilizada por detalles de receta, detalles de compra, cambios o consumos de venta que requieran conservarla. | Q21: La unidad de medida esta siendo utilizada por un detalle de receta, un detalle de compra, un cambio o un consumo de venta. | R21: Rechazar la eliminacion e informar en que registros esta en uso la unidad de medida.

Sheet E-UnidadMedida
A1: <<<Modelo de Dominio | B1: <<<Objetos de Dominio
A2: Objeto de Dominio: | B2: UnidadMedida
A3: Descripción: | B3: ='C-UnidadMedida'!B3 -> Es la unidad con la que se mide cada ingrediente o producto, por ejemplo kilos, litros o unidades.
A4: Actor | B4: Action/Command | D4: Entity/Aggregate/Object domain | E4: Read Model | G4: Business Rule/Policy | H4: Domain Event | I4: Hotspot/questions/Risk
A5: Actor | B5: Acción | C5: Descripción | D5: Objeto de dominio | E5: Información externa | G5: Políticas | H5: Evento | I5: Aspectos por solucionar
E6: Información | F6: Descripción | G6: Número
A7: Administrador | B7: Consultar unidades de medida disponibles | C7: Permite consultar las unidades de medida precargadas en el sistema para seleccionar la unidad adecuada al registrar cantidades de productos, ingredientes, compras, recetas o movimientos de inventario. | D7: UnidadMedida | G7: =HYPERLINK("#'P-UnidadMedida'!A5", "P-UM-001") -> P-UM-001 | H7: Unidades de medida consultadas
G8: =HYPERLINK("#'P-UnidadMedida'!A6", "P-UM-002") -> P-UM-002
A9: Administrador | B9: Eliminar unidad de medida | C9: Permite eliminar una unidad de medida que no este siendo utilizada por ningun otro registro de la pizzeria. | D9: UnidadMedida | G9: =HYPERLINK("#'P-UnidadMedida'!A7", "P-UM-003") -> P-UM-003 | H9: Unidad de medida eliminada
G10: =HYPERLINK("#'P-UnidadMedida'!A8", "P-UM-004") -> P-UM-004
G11: =HYPERLINK("#'P-UnidadMedida'!A9", "P-UM-005") -> P-UM-005

Sheet P-UnidadMedida
A1: <<<Modelo de Dominio | B1: <<<Objetos de Dominio
A2: Objeto de Dominio | B2: UnidadMedida
A3: Descripcion | B3: ='C-UnidadMedida'!B3 -> Es la unidad con la que se mide cada ingrediente o producto, por ejemplo kilos, litros o unidades.
A4: Numero politica | B4: Descripcion Politica | C4: Objeto Responsable | D4: Regla Referenciada
A5: P-UM-001 | B5: Asegurar que solo se consulten las unidades de medida del catalogo definido por la pizzeria (g, kg, ml, l y und), cada una con su tipo de medida (Peso, Volumen o Unidad). | C5: UnidadMedida
A6: P-UM-002 | B6: Asegurar que la unidad de medida exista con el identificador indicado | C6: UnidadMedida
A7: P-UM-003 | B7: Asegurar que la unidad de medida que se desea eliminar se encuentre registrada en el sistema. | C7: UnidadMedida
A8: P-UM-004 | B8: Asegurar que la unidad de medida que se desea eliminar no este siendo utilizada por productos internos, lotes o registros de inventario que requieran conservarla. | C8: UnidadMedida
A9: P-UM-005 | B9: Asegurar que la unidad de medida que se desea eliminar no este siendo utilizada por detalles de receta, detalles de compra, cambios o consumos de venta que requieran conservarla. | C9: UnidadMedida

Sheet M-TipoProducto
A1: <<<Modelo de Dominio | B1: <<<Objetos de Dominio
A2: Representa el identificador unico de cada producto | B2: Nombre del tipo de producto (Pizza, Bebida o Adicion)
A3: Tipo de dato | B3: Alfanumerico(max 20 caracteres)
A6: Obligatorio | B6: Si
A7: Id | B7: Nombre
A8: 1 | B8: Pizza
A9: 2 | B9: Bebida
A10: 3 | B10: Adicion

Sheet C-TipoProducto
A1: <<<Modelo de Dominio | B1: <<<Objetos de Dominio
A2: Nombre | B2: TipoProducto
A3: Descripción | B3: =HYPERLINK("#'Objetos de dominio'!B5", 'Objetos de dominio'!B5) -> Indica en qué categoría entra cada producto que vende la pizzería, por ejemplo si es una pizza, una bebida o una adición.
A4: Nombre atributo | B4: Descripción atributo | C4: Identificador del objeto de dominio | D4: Tipo de dato | E4: Obligatorio | F4: Longitud mínima (si aplica) | G4: Longitud máxima (si aplica) | H4: Precisión (si aplica) | I4: Rendondeo (si aplica) | J4: Rango inicial (si aplica) | K4: Rango final (si aplica) | L4: Formato (si aplica) | M4: Reglas especiales (si aplica) | N4: Dato calculado | O4: Aplica ajuste del dato (si aplica) | P4: Carácter de ajuste (si aplica) | Q4: Quitar espacios en blanco al inicio (si aplica) | R4: Quitar espacios en blanco al fin (si aplica) | S4: Dato sensible (si aplica) | T4: Valor por defecto (si aplica) | U4: Auto generado | V4: =HYPERLINK("#'C-TipoProducto'!A18", 'C-TipoProducto'!A18) -> Consultar tipos de producto disponibles | W4: =HYPERLINK("#'C-TipoProducto'!A19", 'C-TipoProducto'!A19) -> Registrar tipo de producto | X4: =HYPERLINK("#'C-TipoProducto'!A21", 'C-TipoProducto'!A21) -> Actualizar tipo de producto | Z4: =HYPERLINK("#'C-TipoProducto'!A23", 'C-TipoProducto'!A23) -> Eliminar tipo de producto
A5: =HYPERLINK("#'M-TipoProducto'!A7", 'M-TipoProducto'!A7) -> Id | B5: =HYPERLINK("#'M-TipoProducto'!A2", 'M-TipoProducto'!A2) -> Representa el identificador unico de cada producto | C5: Si | D5: Identificador unico universal | E5: Si | N5: No | O5: No | Q5: No | R5: No | S5: No | U5: Si | V5: No Mostrar | W5: No Requerido | X5: Requerido | Y5: No Modificable | Z5: Requerido
A6: =HYPERLINK("#'M-TipoProducto'!B7", 'M-TipoProducto'!B7) -> Nombre | B6: =HYPERLINK("#'M-TipoProducto'!B2", 'M-TipoProducto'!B2) -> Nombre del tipo de producto (Pizza, Bebida o Adicion) | C6: No | D6: Alfanumerico | E6: Si | F6: 1 | G6: 20 | M6: Estos son los tipos de producto con los que arranca el catalogo (Pizza, Bebida, Adicion), pero se pueden agregar nuevos si la pizzeria llega a manejar una categoria de producto distinta. | N6: No | O6: No | Q6: Si | R6: Si | S6: No | U6: No | V6: Mostrar | W6: Requerido | X6: Requerido | Y6: Modificable | Z6: No Requerido
A11: Nombre combinación única | B11: Descripción | C11: Atributos involucrados
A12: Combinación única 1 | B12: No pueden existir dos tipos de producto con el mismo Nombre. | C12: =HYPERLINK("#'C-TipoProducto'!A6", 'C-TipoProducto'!A6) -> Nombre
A16: Responsabilidad | C16: Descripción | G16: Entradas | J16: Salida | O16: Políticas (Reglas de Negocio) | Q16: Excepción
G17: Parámetro | H17: Tipo de dato | I17: Descripción | J17: Tipo de Dato | K17: Descripción | O17: Política | P17: Descripción | Q17: Detalle | R17: ¿Qué hago?
A18: =HYPERLINK("#'C-TipoProducto'!V4", 'E-TipoProducto'!B7) -> Consultar tipos de producto disponibles | C18: ='E-TipoProducto'!C7 -> Permite consultar los tipos de producto disponibles en el sistema para clasificar un producto. | G18: id | H18: UUID | I18: Id necesario para realizar la consulta de los tipos de producto disponibles. | J18: Lista de Tipos de Producto | K18: Conjunto de tipos de producto registrados y disponibles para selección. | O18: =HYPERLINK("#'P-TipoProducto'!A5", 'P-TipoProducto'!A5) -> P-TP-001 | P18: ='P-TipoProducto'!B5 -> Asegurar que el tipo de producto exista con el identificador indicado. | Q18: No existen tipos de producto disponibles. | R18: Informar que el tipo de producto que está buscando no existe.
A19: =HYPERLINK("#'E-TipoProducto'!B8", 'E-TipoProducto'!B8) -> Registrar tipo de producto | C19: ='E-TipoProducto'!C8 -> Permite agregar un nuevo tipo de producto al catalogo, para cuando la pizzeria empiece a manejar una categoria de producto que no exista todavia. | G19: Nombre | H19: Alfanumerico | I19: Nombre del nuevo tipo de producto que se desea registrar. | J19: TipoProducto | K19: Tipo de producto registrado. | O19: =HYPERLINK("#'P-TipoProducto'!A6", 'P-TipoProducto'!A6) -> P-TP-002 | P19: ='P-TipoProducto'!B6 -> Asegurar que los datos ingresados sean validos segun el tipo de dato, la obligatoriedad y el formato correspondiente. | Q19: El dato ingresado no es valido segun el tipo de dato, la obligatoriedad o el formato esperado. | R19: Rechazar el registro e informar cual dato no es valido y por que.
O20: =HYPERLINK("#'P-TipoProducto'!A7", 'P-TipoProducto'!A7) -> P-TP-003 | P20: ='P-TipoProducto'!B7 -> Asegurar que no exista otro tipo de producto con el mismo Nombre al registrarlo. | Q20: Ya existe otro tipo de producto registrado con el mismo Nombre. | R20: Rechazar el registro e informar que ya existe un tipo de producto con ese Nombre.
A21: =HYPERLINK("#'E-TipoProducto'!B10", 'E-TipoProducto'!B10) -> Actualizar tipo de producto | C21: ='E-TipoProducto'!C10 -> Permite modificar el nombre de un tipo de producto que ya existe. | G21: Id | H21: UUID | I21: Identificador del tipo de producto que se desea modificar, junto con el nuevo Nombre. | J21: TipoProducto | K21: Tipo de producto actualizado. | O21: =HYPERLINK("#'P-TipoProducto'!A8", 'P-TipoProducto'!A8) -> P-TP-004 | P21: ='P-TipoProducto'!B8 -> Asegurar que el tipo de producto que se desea modificar se encuentre registrado en el sistema. | Q21: El tipo de producto no existe en el sistema. | R21: Rechazar la actualizacion e informar que el tipo de producto no existe.
O22: =HYPERLINK("#'P-TipoProducto'!A6", 'P-TipoProducto'!A6) -> P-TP-002 | P22: ='P-TipoProducto'!B6 -> Asegurar que los datos ingresados sean validos segun el tipo de dato, la obligatoriedad y el formato correspondiente. | Q22: El nuevo dato ingresado no es valido segun el tipo de dato, la obligatoriedad o el formato esperado. | R22: Rechazar la actualizacion e informar cual dato no es valido y por que.
A23: =HYPERLINK("#'E-TipoProducto'!B12", 'E-TipoProducto'!B12) -> Eliminar tipo de producto | C23: ='E-TipoProducto'!C12 -> Permite eliminar un tipo de producto que no tenga productos asociados que deban conservarse. | G23: Id | H23: UUID | I23: Identificador del tipo de producto que se desea eliminar. | J23: TipoProducto | K23: Tipo de producto eliminado correctamente. | O23: =HYPERLINK("#'P-TipoProducto'!A9", 'P-TipoProducto'!A9) -> P-TP-005 | P23: ='P-TipoProducto'!B9 -> Asegurar que un tipo de producto no pueda eliminarse cuando tenga productos asociados que deban conservarse para mantener la trazabilidad. | Q23: El tipo de producto tiene productos asociados que deben conservarse. | R23: Rechazar la eliminacion e informar que el tipo de producto tiene productos asociados.
O24: =HYPERLINK("#'P-TipoProducto'!A10", 'P-TipoProducto'!A10) -> P-TP-006 | P24: ='P-TipoProducto'!B10 -> Asegurar que el tipo de producto que se desea eliminar exista con el identificador indicado. | Q24: El tipo de producto no existe en el sistema. | R24: Rechazar la eliminacion e informar que el tipo de producto no existe.

Sheet E-TipoProducto
A1: <<<Modelo de Dominio | B1: <<<Objetos de Dominio
A2: Objeto de Dominio: | B2: TipoProducto
A3: Descripción: | B3: ='C-TipoProducto'!B3 -> Indica en qué categoría entra cada producto que vende la pizzería, por ejemplo si es una pizza, una bebida o una adición.
A4: Actor | B4: Action/Command | D4: Entity/Aggregate/Object domain | E4: Read Model | G4: Business Rule/Policy | H4: External System | I4: Domain Event | J4: Hotspot/questions/Risk
A5: Actor | B5: Acción | C5: Descripción | D5: Objeto de dominio | E5: Información externa | G5: Políticas | H5: Sistema Externo | I5: Evento | J5: Aspectos por solucionar
E6: Información | F6: Descripción | G6: Número
A7: Administrador | B7: Consultar tipos de producto disponibles | C7: Permite consultar los tipos de producto disponibles en el sistema para clasificar un producto. | D7: TipoProducto | G7: =HYPERLINK("#'P-TipoProducto'!A5", "P-TP-001") -> P-TP-001 | I7: Tipos de producto consultados
A8: Administrador | B8: Registrar tipo de producto | C8: Permite agregar un nuevo tipo de producto al catalogo, para cuando la pizzeria empiece a manejar una categoria de producto que no exista todavia. | D8: TipoProducto | G8: =HYPERLINK("#'P-TipoProducto'!A6", "P-TP-002") -> P-TP-002 | I8: Tipo de producto registrado
G9: =HYPERLINK("#'P-TipoProducto'!A7", "P-TP-003") -> P-TP-003
A10: Administrador | B10: Actualizar tipo de producto | C10: Permite modificar el nombre de un tipo de producto que ya existe. | D10: TipoProducto | G10: =HYPERLINK("#'P-TipoProducto'!A8", "P-TP-004") -> P-TP-004 | I10: Tipo de producto actualizado
G11: =HYPERLINK("#'P-TipoProducto'!A6", "P-TP-002") -> P-TP-002
A12: Administrador | B12: Eliminar tipo de producto | C12: Permite eliminar un tipo de producto que no tenga productos asociados que deban conservarse. | D12: TipoProducto | G12: =HYPERLINK("#'P-TipoProducto'!A9", "P-TP-005") -> P-TP-005 | I12: Tipo de producto eliminado
G13: =HYPERLINK("#'P-TipoProducto'!A10", "P-TP-006") -> P-TP-006

Sheet P-TipoProducto
A1: <<<Modelo de Dominio | B1: <<<Objetos de Dominio
A2: Objeto de Dominio | B2: TipoProducto
A3: Descripcion | B3: ='C-TipoProducto'!B3 -> Indica en qué categoría entra cada producto que vende la pizzería, por ejemplo si es una pizza, una bebida o una adición.
A4: Numero politica | B4: Descripcion Politica | C4: Objeto Responsable | D4: Regla Referenciada
A5: P-TP-001 | B5: Asegurar que el tipo de producto exista con el identificador indicado. | C5: TipoProducto
A6: P-TP-002 | B6: Asegurar que los datos ingresados sean validos segun el tipo de dato, la obligatoriedad y el formato correspondiente. | C6: TipoProducto
A7: P-TP-003 | B7: Asegurar que no exista otro tipo de producto con el mismo Nombre al registrarlo. | C7: TipoProducto
A8: P-TP-004 | B8: Asegurar que el tipo de producto que se desea modificar se encuentre registrado en el sistema. | C8: TipoProducto
A9: P-TP-005 | B9: Asegurar que un tipo de producto no pueda eliminarse cuando tenga productos asociados que deban conservarse para mantener la trazabilidad. | C9: TipoProducto
A10: P-TP-006 | B10: Asegurar que el tipo de producto que se desea eliminar exista con el identificador indicado. | C10: TipoProducto

Sheet M-ClaseMovimiento
A1: <<<Modelo de Dominio | B1: <<<Objetos de Dominio
A2: Representa el identificador unico de cada clase de movimiento | B2: Nombre de la clase de movimiento (Entrada o Salida): indica si el movimiento suma (Entrada) o resta (Salida) inventario
A3: Tipo de dato | B3: Alfanumerico(max 10 caracteres)
A6: Obligatorio | B6: Si
A7: Id | B7: Nombre
A8: 1 | B8: Entrada
A9: 2 | B9: Salida

Sheet C-ClaseMovimiento
A1: <<<Modelo de Dominio | B1: <<<Objetos de Dominio
A2: Nombre | B2: ClaseMovimiento
A3: Descripción | B3: =HYPERLINK("#'Objetos de dominio'!B6", 'Objetos de dominio'!B6) -> Indica si un movimiento de inventario fue una entrada o una salida de insumos o productos.
A4: Nombre atributo | B4: Descripción atributo | C4: Identificador del objeto de dominio | D4: Tipo de dato | E4: Obligatorio | F4: Longitud mínima (si aplica) | G4: Longitud máxima (si aplica) | H4: Precisión (si aplica) | I4: Rendondeo (si aplica) | J4: Rango inicial (si aplica) | K4: Rango final (si aplica) | L4: Formato (si aplica) | M4: Reglas especiales (si aplica) | N4: Dato calculado | O4: Aplica ajuste del dato (si aplica) | P4: Carácter de ajuste (si aplica) | Q4: Quitar espacios en blanco al inicio (si aplica) | R4: Quitar espacios en blanco al fin (si aplica) | S4: Dato sensible (si aplica) | T4: Valor por defecto (si aplica) | U4: Auto generado | V4: =HYPERLINK("#'C-ClaseMovimiento'!A19", 'C-ClaseMovimiento'!A19) -> Consultar clases de movimiento disponibles
A5: =HYPERLINK("#'M-ClaseMovimiento'!A7", 'M-ClaseMovimiento'!A7) -> Id | B5: =HYPERLINK("#'M-ClaseMovimiento'!A2", 'M-ClaseMovimiento'!A2) -> Representa el identificador unico de cada clase de movimiento | C5: Si | D5: Identificador unico universal | E5: Si | N5: No | O5: No | Q5: No | R5: No | S5: No | U5: Si | V5: No Mostrar
A6: =HYPERLINK("#'M-ClaseMovimiento'!B7", 'M-ClaseMovimiento'!B7) -> Nombre | B6: =HYPERLINK("#'M-ClaseMovimiento'!B2", 'M-ClaseMovimiento'!B2) -> Nombre de la clase de movimiento (Entrada o Salida): indica si el movimiento suma (Entrada) o resta (Salida) inventario | C6: No | D6: Alfanumerico | E6: Si | F6: 1 | G6: 10 | M6: Catalogo fijo de solo 2 valores (Entrada, Salida) | N6: No | O6: No | Q6: Si | R6: Si | S6: No | U6: No | V6: Mostrar
A12: Nombre combinación única | B12: Descripción | C12: Atributos involucrados
A13: Combinación única 1 | B13: No pueden existir dos clases de movimiento con el mismo Nombre. | C13: =HYPERLINK("#'C-ClaseMovimiento'!A6", 'C-ClaseMovimiento'!A6) -> Nombre
A17: Responsabilidad | C17: Descripción | G17: Entradas | J17: Salida | O17: Políticas (Reglas de Negocio) | Q17: Excepción
G18: Parámetro | H18: Tipo de dato | I18: Descripción | J18: Tipo de Dato | K18: Descripción | O18: Política | P18: Descripción | Q18: Detalle | R18: ¿Qué hago?
A19: =HYPERLINK("#'C-ClaseMovimiento'!V4", 'E-ClaseMovimiento'!B7) -> Consultar clases de movimiento disponibles | C19: ='E-ClaseMovimiento'!C7 -> Permite consultar las clases de movimiento (Entrada o Salida) disponibles para clasificar un movimiento de inventario. | G19: id | H19: UUID | I19: Id necesario para realizar la consulta de las clases de movimiento disponibles. | J19: Lista de ClasesMovimiento | K19: Conjunto de clases de movimiento (Entrada y Salida) disponibles para seleccion. | O19: =HYPERLINK("#'P-ClaseMovimiento'!A5", 'P-ClaseMovimiento'!A5) -> P-CM-001 | P19: ='P-ClaseMovimiento'!B5 -> Asegurar que la clase de movimiento exista con el identificador indicado. | Q19: No existen clases de movimiento disponibles. | R19: Informar que la clase de movimiento que esta buscando no existe.

Sheet E-ClaseMovimiento
A1: <<<Modelo de Dominio | B1: <<<Objetos de Dominio
A2: Objeto de Dominio: | B2: ClaseMovimiento
A3: Descripción: | B3: ='C-ClaseMovimiento'!B3 -> Indica si un movimiento de inventario fue una entrada o una salida de insumos o productos.
A4: Actor | B4: Action/Command | D4: Entity/Aggregate/Object domain | E4: Read Model | G4: Business Rule/Policy | H4: External System | I4: Domain Event | J4: Hotspot/questions/Risk
A5: Actor | B5: Acción | C5: Descripción | D5: Objeto de dominio | E5: Información externa | G5: Políticas | H5: Sistema Externo | I5: Evento | J5: Aspectos por solucionar
E6: Información | F6: Descripción | G6: Número
A7: Administrador | B7: Consultar clases de movimiento disponibles | C7: Permite consultar las clases de movimiento (Entrada o Salida) disponibles para clasificar un movimiento de inventario. | D7: ClaseMovimiento | G7: =HYPERLINK("#'P-ClaseMovimiento'!A5", "P-CM-001") -> P-CM-001 | I7: Clases de movimiento consultadas

Sheet P-ClaseMovimiento
A1: <<<Modelo de Dominio | B1: <<<Objetos de Dominio
A2: Objeto de Dominio | B2: ClaseMovimiento
A3: Descripcion | B3: ='C-ClaseMovimiento'!B3 -> Indica si un movimiento de inventario fue una entrada o una salida de insumos o productos.
A4: Numero politica | B4: Descripcion Politica | C4: Objeto Responsable | D4: Regla Referenciada
A5: P-CM-001 | B5: Asegurar que la clase de movimiento exista con el identificador indicado. | C5: ClaseMovimiento

Sheet M-Tamaño
A1: <<<Modelo de Dominio | B1: <<<Objetos de Dominio
A2: Representa el identificador unico de cada tamaño | B2: Nombre del tamaño (Grande, Mediana, Pequeña o No aplica)
A3: Tipo de dato | B3: Alfanumerico(max 20 caracteres)
A6: Obligatorio | B6: Si
A7: Id | B7: Tamaño
A8: 1 | B8: Grande
A9: 2 | B9: Mediana
A10: 3 | B10: Pequeña
A11: 4 | B11: No aplica

Sheet C-Tamaño
A1: <<<Modelo de Dominio | B1: <<<Objetos de Dominio
A2: Nombre | B2: Tamaño
A3: Descripción | B3: =HYPERLINK("#'Objetos de dominio'!B7", 'Objetos de dominio'!B7) -> Son los distintos tamaños en los que la pizzería puede ofrecer una pizza.
A4: Nombre atributo | B4: Descripción atributo | C4: Identificador del objeto de dominio | D4: Tipo de dato | E4: Obligatorio | F4: Longitud mínima (si aplica) | G4: Longitud máxima (si aplica) | H4: Precisión (si aplica) | I4: Rendondeo (si aplica) | J4: Rango inicial (si aplica) | K4: Rango final (si aplica) | L4: Formato (si aplica) | M4: Reglas especiales (si aplica) | N4: Dato calculado | O4: Aplica ajuste del dato (si aplica) | P4: Carácter de ajuste (si aplica) | Q4: Quitar espacios en blanco al inicio (si aplica) | R4: Quitar espacios en blanco al fin (si aplica) | S4: Dato sensible (si aplica) | T4: Valor por defecto (si aplica) | U4: Auto generado | V4: =HYPERLINK("#'C-Tamaño'!A18", 'C-Tamaño'!A18) -> Consultar tamaños disponibles | W4: =HYPERLINK("#'C-Tamaño'!A19", 'C-Tamaño'!A19) -> Registrar tamaño | X4: =HYPERLINK("#'C-Tamaño'!A21", 'C-Tamaño'!A21) -> Actualizar tamaño | Z4: =HYPERLINK("#'C-Tamaño'!A23", 'C-Tamaño'!A23) -> Eliminar tamaño
A5: =HYPERLINK("#'M-Tamaño'!A7", 'M-Tamaño'!A7) -> Id | B5: =HYPERLINK("#'M-Tamaño'!A2", 'M-Tamaño'!A2) -> Representa el identificador unico de cada tamaño | C5: Si | D5: Identificador unico universal | E5: Si | N5: No | O5: No | Q5: No | R5: No | S5: No | U5: Si | V5: No Mostrar | W5: No Requerido | X5: Requerido | Y5: No Modificable | Z5: Requerido
A6: =HYPERLINK("#'M-Tamaño'!B7", 'M-Tamaño'!B7) -> Tamaño | B6: =HYPERLINK("#'M-Tamaño'!B2", 'M-Tamaño'!B2) -> Nombre del tamaño (Grande, Mediana, Pequeña o No aplica) | C6: No | D6: Alfanumerico | E6: Si | F6: 1 | G6: 20 | M6: Estos son los tamaños con los que arranca el catalogo (Grande, Mediana, Pequeña, No aplica), pero se pueden agregar nuevos si la pizzeria llega a manejar una presentacion de tamaño distinta. | N6: No | O6: No | Q6: Si | R6: Si | S6: No | U6: No | V6: Mostrar | W6: Requerido | X6: Requerido | Y6: Modificable | Z6: No Requerido
A11: Nombre combinación única | B11: Descripción | C11: Atributos involucrados
A12: Combinación única 1 | B12: No pueden existir dos tamaños con el mismo Nombre. | C12: =HYPERLINK("#'C-Tamaño'!A6", 'C-Tamaño'!A6) -> Tamaño
A16: Responsabilidad | C16: Descripción | G16: Entradas | J16: Salida | O16: Políticas (Reglas de Negocio) | Q16: Excepción
G17: Parámetro | H17: Tipo de dato | I17: Descripción | J17: Tipo de Dato | K17: Descripción | O17: Política | P17: Descripción | Q17: Detalle | R17: ¿Qué hago?
A18: =HYPERLINK("#'C-Tamaño'!V4", 'E-Tamaño'!B7) -> Consultar tamaños disponibles | C18: ='E-Tamaño'!C7 -> Permite consultar los tamaños disponibles en el sistema para definir el tamaño de un producto. | G18: id | H18: UUID | I18: Id necesario para realizar la consulta de los tamaños disponibles. | J18: Lista de Tamaños | K18: Conjunto de tamaños registrados y disponibles para selección. | O18: =HYPERLINK("#'P-Tamaño'!A5", 'P-Tamaño'!A5) -> P-TAM-001 | P18: ='P-Tamaño'!B5 -> Asegurar que el tamaño exista con el identificador indicado. | Q18: No existen tamaños disponibles. | R18: Informar que el tamaño que está buscando no existe.
A19: =HYPERLINK("#'E-Tamaño'!B8", 'E-Tamaño'!B8) -> Registrar tamaño | C19: ='E-Tamaño'!C8 -> Permite agregar un nuevo tamaño al catalogo, para cuando la pizzeria empiece a ofrecer una presentacion que no exista todavia. | G19: Nombre | H19: Alfanumerico | I19: Nombre del nuevo tamaño que se desea registrar. | J19: Tamaño | K19: Tamaño registrado. | O19: =HYPERLINK("#'P-Tamaño'!A6", 'P-Tamaño'!A6) -> P-TAM-002 | P19: ='P-Tamaño'!B6 -> Asegurar que los datos ingresados sean validos segun el tipo de dato, la obligatoriedad y el formato correspondiente. | Q19: El dato ingresado no es valido segun el tipo de dato, la obligatoriedad o el formato esperado. | R19: Rechazar el registro e informar cual dato no es valido y por que.
O20: =HYPERLINK("#'P-Tamaño'!A7", 'P-Tamaño'!A7) -> P-TAM-003 | P20: ='P-Tamaño'!B7 -> Asegurar que no exista otro tamaño con el mismo Nombre al registrarlo. | Q20: Ya existe otro tamaño registrado con el mismo Nombre. | R20: Rechazar el registro e informar que ya existe un tamaño con ese Nombre.
A21: =HYPERLINK("#'E-Tamaño'!B10", 'E-Tamaño'!B10) -> Actualizar tamaño | C21: ='E-Tamaño'!C10 -> Permite modificar el nombre de un tamaño que ya existe. | G21: Id | H21: UUID | I21: Identificador del tamaño que se desea modificar, junto con el nuevo Nombre. | J21: Tamaño | K21: Tamaño actualizado. | O21: =HYPERLINK("#'P-Tamaño'!A8", 'P-Tamaño'!A8) -> P-TAM-004 | P21: ='P-Tamaño'!B8 -> Asegurar que el tamaño que se desea modificar se encuentre registrado en el sistema. | Q21: El tamaño no existe en el sistema. | R21: Rechazar la actualizacion e informar que el tamaño no existe.
O22: =HYPERLINK("#'P-Tamaño'!A6", 'P-Tamaño'!A6) -> P-TAM-002 | P22: ='P-Tamaño'!B6 -> Asegurar que los datos ingresados sean validos segun el tipo de dato, la obligatoriedad y el formato correspondiente. | Q22: El nuevo dato ingresado no es valido segun el tipo de dato, la obligatoriedad o el formato esperado. | R22: Rechazar la actualizacion e informar cual dato no es valido y por que.
A23: =HYPERLINK("#'E-Tamaño'!B12", 'E-Tamaño'!B12) -> Eliminar tamaño | C23: ='E-Tamaño'!C12 -> Permite eliminar un tamaño que no tenga productos asociados que deban conservarse. | G23: Id | H23: UUID | I23: Identificador del tamaño que se desea eliminar. | J23: Tamaño | K23: Tamaño eliminado correctamente. | O23: =HYPERLINK("#'P-Tamaño'!A9", 'P-Tamaño'!A9) -> P-TAM-005 | P23: ='P-Tamaño'!B9 -> Asegurar que un tamaño no pueda eliminarse cuando tenga productos asociados que deban conservarse para mantener la trazabilidad. | Q23: El tamaño tiene productos asociados que deben conservarse. | R23: Rechazar la eliminacion e informar que el tamaño tiene productos asociados.
O24: =HYPERLINK("#'P-Tamaño'!A10", 'P-Tamaño'!A10) -> P-TAM-006 | P24: ='P-Tamaño'!B10 -> Asegurar que el tamaño que se desea eliminar exista con el identificador indicado. | Q24: El tamaño no existe en el sistema. | R24: Rechazar la eliminacion e informar que el tamaño no existe.

Sheet E-Tamaño
A1: <<<Modelo de Dominio | B1: <<<Objetos de Dominio
A2: Objeto de Dominio: | B2: Tamaño
A3: Descripción: | B3: ='C-Tamaño'!B3 -> Son los distintos tamaños en los que la pizzería puede ofrecer una pizza.
A4: Actor | B4: Action/Command | D4: Entity/Aggregate/Object domain | E4: Read Model | G4: Business Rule/Policy | H4: External System | I4: Domain Event | J4: Hotspot/questions/Risk
A5: Actor | B5: Acción | C5: Descripción | D5: Objeto de dominio | E5: Información externa | G5: Políticas | H5: Sistema Externo | I5: Evento | J5: Aspectos por solucionar
E6: Información | F6: Descripción | G6: Número
A7: Administrador | B7: Consultar tamaños disponibles | C7: Permite consultar los tamaños disponibles en el sistema para definir el tamaño de un producto. | D7: Tamaño | G7: =HYPERLINK("#'P-Tamaño'!A5", "P-TAM-001") -> P-TAM-001 | I7: Tamaños consultados
A8: Administrador | B8: Registrar tamaño | C8: Permite agregar un nuevo tamaño al catalogo, para cuando la pizzeria empiece a ofrecer una presentacion que no exista todavia. | D8: Tamaño | G8: =HYPERLINK("#'P-Tamaño'!A6", "P-TAM-002") -> P-TAM-002 | I8: Tamaño registrado
G9: =HYPERLINK("#'P-Tamaño'!A7", "P-TAM-003") -> P-TAM-003
A10: Administrador | B10: Actualizar tamaño | C10: Permite modificar el nombre de un tamaño que ya existe. | D10: Tamaño | G10: =HYPERLINK("#'P-Tamaño'!A8", "P-TAM-004") -> P-TAM-004 | I10: Tamaño actualizado
G11: =HYPERLINK("#'P-Tamaño'!A6", "P-TAM-002") -> P-TAM-002
A12: Administrador | B12: Eliminar tamaño | C12: Permite eliminar un tamaño que no tenga productos asociados que deban conservarse. | D12: Tamaño | G12: =HYPERLINK("#'P-Tamaño'!A9", "P-TAM-005") -> P-TAM-005 | I12: Tamaño eliminado
G13: =HYPERLINK("#'P-Tamaño'!A10", "P-TAM-006") -> P-TAM-006

Sheet P-Tamaño
A1: <<<Modelo de Dominio | B1: <<<Objetos de Dominio
A2: Objeto de Dominio | B2: Tamaño
A3: Descripcion | B3: ='C-Tamaño'!B3 -> Son los distintos tamaños en los que la pizzería puede ofrecer una pizza.
A4: Numero politica | B4: Descripcion Politica | C4: Objeto Responsable | D4: Regla Referenciada
A5: P-TAM-001 | B5: Asegurar que el tamaño exista con el identificador indicado. | C5: Tamaño
A6: P-TAM-002 | B6: Asegurar que los datos ingresados sean validos segun el tipo de dato, la obligatoriedad y el formato correspondiente. | C6: Tamaño
A7: P-TAM-003 | B7: Asegurar que no exista otro tamaño con el mismo Nombre al registrarlo. | C7: Tamaño
A8: P-TAM-004 | B8: Asegurar que el tamaño que se desea modificar se encuentre registrado en el sistema. | C8: Tamaño
A9: P-TAM-005 | B9: Asegurar que un tamaño no pueda eliminarse cuando tenga productos asociados que deban conservarse para mantener la trazabilidad. | C9: Tamaño
A10: P-TAM-006 | B10: Asegurar que el tamaño que se desea eliminar exista con el identificador indicado. | C10: Tamaño

Sheet M-CategoriaOrigen
A1: <<<Modelo de Dominio | B1: <<<Objetos de Dominio
A2: Representa el identificador unico de cada categoria de origen | B2: Nombre de la categoria de origen: indica de donde proviene la operacion (Compra, Venta o Cambio)
A3: Tipo de dato | B3: Alfanumerico(max 10 caracteres)
A6: Obligatorio | B6: Si
A7: Id | B7: Nombre
A8: 1 | B8: Compra
A9: 2 | B9: Venta
A10: 3 | B10: Cambio

Sheet C-CategoriaOrigen
A1: <<<Modelo de Dominio | B1: <<<Objetos de Dominio
A2: Nombre | B2: CategoriaOrigen
A3: Descripción | B3: =HYPERLINK("#'Objetos de dominio'!B8", 'Objetos de dominio'!B8) -> Indica qué operación fue la que generó un movimiento de inventario: una compra, una venta, un cambio de un producto que no es perecedero, o el retiro de un lote (porque se cambió o porque se venció).
A4: Nombre atributo | B4: Descripción atributo | C4: Identificador del objeto de dominio | D4: Tipo de dato | E4: Obligatorio | F4: Longitud mínima (si aplica) | G4: Longitud máxima (si aplica) | H4: Precisión (si aplica) | I4: Rendondeo (si aplica) | J4: Rango inicial (si aplica) | K4: Rango final (si aplica) | L4: Formato (si aplica) | M4: Reglas especiales (si aplica) | N4: Dato calculado | O4: Aplica ajuste del dato (si aplica) | P4: Carácter de ajuste (si aplica) | Q4: Quitar espacios en blanco al inicio (si aplica) | R4: Quitar espacios en blanco al fin (si aplica) | S4: Dato sensible (si aplica) | T4: Valor por defecto (si aplica) | U4: Auto generado | V4: =HYPERLINK("#'C-CategoriaOrigen'!A18", 'C-CategoriaOrigen'!A18) -> Consultar categorias de origen disponibles
A5: =HYPERLINK("#'M-CategoriaOrigen'!A7", 'M-CategoriaOrigen'!A7) -> Id | B5: =HYPERLINK("#'M-CategoriaOrigen'!A2", 'M-CategoriaOrigen'!A2) -> Representa el identificador unico de cada categoria de origen | C5: Si | D5: Identificador unico universal | E5: Si | N5: No | O5: No | Q5: No | R5: No | S5: No | U5: Si | V5: No Mostrar
A6: =HYPERLINK("#'M-CategoriaOrigen'!B7", 'M-CategoriaOrigen'!B7) -> Nombre | B6: =HYPERLINK("#'M-CategoriaOrigen'!B2", 'M-CategoriaOrigen'!B2) -> Nombre de la categoria de origen: indica de donde proviene la operacion (Compra, Venta o Cambio) | C6: No | D6: Alfanumerico | E6: Si | F6: 1 | G6: 10 | M6: Catalogo fijo de 3 valores (Compra, Venta, Cambio) | N6: No | O6: No | Q6: Si | R6: Si | S6: No | U6: No | V6: Mostrar
A11: Nombre combinación única | B11: Descripción | C11: Atributos involucrados
A12: Combinación única 1 | B12: No pueden existir dos categorias de origen con el mismo Nombre. | C12: =HYPERLINK("#'C-CategoriaOrigen'!A6", 'C-CategoriaOrigen'!A6) -> Nombre
A16: Responsabilidad | C16: Descripción | G16: Entradas | J16: Salida | O16: Políticas (Reglas de Negocio) | Q16: Excepción
G17: Parámetro | H17: Tipo de dato | I17: Descripción | J17: Tipo de Dato | K17: Descripción | O17: Política | P17: Descripción | Q17: Detalle | R17: ¿Qué hago?
A18: =HYPERLINK("#'C-CategoriaOrigen'!V4", 'E-CategoriaOrigen'!B7) -> Consultar categorias de origen disponibles | C18: ='E-CategoriaOrigen'!C7 -> Permite consultar las categorias de origen (Compra, Venta o Cambio) que indican que operacion genero un movimiento de inventario. | G18: id | H18: UUID | I18: Id necesario para realizar la consulta de las categorias de origen disponibles. | J18: Lista de CategoriasOrigen | K18: Conjunto de categorias de origen (Compra, Venta y Cambio) disponibles para seleccion. | O18: =HYPERLINK("#'P-CategoriaOrigen'!A5", 'P-CategoriaOrigen'!A5) -> P-ORI-001 | P18: ='P-CategoriaOrigen'!B5 -> Asegurar que la categoria de origen exista con el identificador indicado. | Q18: No existen categorias de origen disponibles. | R18: Informar que la categoria de origen que esta buscando no existe.

Sheet E-CategoriaOrigen
A1: <<<Modelo de Dominio | B1: <<<Objetos de Dominio
A2: Objeto de Dominio: | B2: CategoriaOrigen
A3: Descripción: | B3: ='C-CategoriaOrigen'!B3 -> Indica qué operación fue la que generó un movimiento de inventario: una compra, una venta, un cambio de un producto que no es perecedero, o el retiro de un lote (porque se cambió o porque se venció).
A4: Actor | B4: Action/Command | D4: Entity/Aggregate/Object domain | E4: Read Model | G4: Business Rule/Policy | H4: External System | I4: Domain Event | J4: Hotspot/questions/Risk
A5: Actor | B5: Acción | C5: Descripción | D5: Objeto de dominio | E5: Información externa | G5: Políticas | H5: Sistema Externo | I5: Evento | J5: Aspectos por solucionar
E6: Información | F6: Descripción | G6: Número
A7: Administrador | B7: Consultar categorias de origen disponibles | C7: Permite consultar las categorias de origen (Compra, Venta o Cambio) que indican que operacion genero un movimiento de inventario. | D7: CategoriaOrigen | G7: =HYPERLINK("#'P-CategoriaOrigen'!A5", "P-ORI-001") -> P-ORI-001 | I7: Categorias de origen consultadas

Sheet P-CategoriaOrigen
A1: <<<Modelo de Dominio | B1: <<<Objetos de Dominio
A2: Objeto de Dominio | B2: CategoriaOrigen
A3: Descripcion | B3: ='C-CategoriaOrigen'!B3 -> Indica qué operación fue la que generó un movimiento de inventario: una compra, una venta, un cambio de un producto que no es perecedero, o el retiro de un lote (porque se cambió o porque se venció).
A4: Numero politica | B4: Descripcion Politica | C4: Objeto Responsable | D4: Regla Referenciada
